Workbook

Sheet 0_README
B1: NBA HOME WIN PROBABILITY MODEL — FULLY FORMULATED EXCEL TWIN
B2: Source of truth: github.com/Risky-Scout/nba-home-win-probability-model · main (DEPLOYED CHAMPION = Elo-only; Elo+rank blend implemented and REJECTED by nested rolling-origin validation)
B4: WHAT THIS WORKBOOK IS
B5: The complete model rebuilt in live Excel formulas from the raw 1,230-game CSV: the Elo rating chain, the Bradley-Terry strengths, the momentum/trend feature, both logistic base models FITTED ON-SHEET by Newton iterations you can read cell by cell, the logistic stacker FITTED ON-SHEET the same way, and the April frozen-snapshot predictions with all four headline metrics. Every stage reconciles against the committed GitHub artifacts, with the reference values shown in blue beside the computed ones and deltas in between.
B7: COLOR LEGEND
B8: BLUE = imported input (raw game data, or a cited repository artifact used as a reconciliation reference). BLACK = live formula. GREEN = link to another sheet. YELLOW = key cells worth pointing at during the presentation.
B10: THE MODEL IN ONE PARAGRAPH
B11: The deployed champion is Elo-only: a margin-of-victory Elo rating difference (K=7.5, home advantage 55, log MOV multiplier on the WINNER-minus-LOSER rating difference) turned into a probability by a standardized, L2-penalized logistic regression fitted on all games through March 31. April team state is frozen at March 31, so no April outcome leaks into any April prediction. An Elo + Bradley-Terry/recent-trend logistic-stack blend was also built and then REJECTED: under nested rolling-origin validation it is worse than Elo-only on log loss and Brier and is worse calibrated.
B13: SHEET MAP — THE STORY IN ORDER
B14: 1_Raw_Games — the task CSV verbatim (md5-identical to data/ in the repo); home_win and margin are derived by formula.
B15: 2_Params — every architecture constant with provenance to artifacts/selected_spec.json. Change K or HFA here and the whole workbook re-derives.
B16: 3_Elo_Chain — 1,230 sequential rating updates. Pregame ratings are running sums of all prior deltas; expected score, MOV multiplier and delta are per-row formulas. Reconciled against outputs/engineered_features.csv (max |delta| shown at top).
... B30: 2_Params (one screen of assumptions) → 3_Elo_Chain (pick any row, walk the update) → 5_BT_Frozen (show the gradient block at ~0, optionally run Solver live) → 8_Fit_Stacker (a, b, c emerging from iterations, matching GitHub) → 10_April_Frozen (probabilities matching the repo per game; metrics matching final_metrics.json) → 11_Dashboard.

Sheet 1_Raw_Games
A1: RAW TASK DATA — nba-win-probability-data.csv (md5 4e80683152aa5b607d84d7f5cefd61f2, identical to repo data/). BLUE = imported; last two columns derived by formula.
A2: game_id | B2: game_date | C2: away | D2: home | E2: away_points | F2: home_points | G2: away_turnovers | H2: home_turnovers | I2: away_fouls | J2: home_fouls | K2: away_rebounds | L2: home_rebounds | M2: away_wins | N2: home_wins | O2: home_win | P2: margin
A3: 0022500001 | B3: 45951 | C3: HOU | D3: OKC | E3: 124 | F3: 125 | G3: 25 | H3: 12 | I3: 26 | J3: 27 | K3: 73 | L3: 49 | M3: 0 | N3: 0 | O3: =IF(F3>E3,1,0) | P3: =F3-E3
A4: 0022500002 | B4: 45951 | C4: GSW | D4: LAL | E4: 119 | F4: 109 | G4: 19 | H4: 20 | I4: 27 | J4: 21 | K4: 41 | L4: 49 | M4: 0 | N4: 0 | O4: =IF(F4>E4,1,0) | P4: =F4-E4
A5: 0022500003 | B5: 45952 | C5: CLE | D5: NYK | E5: 111 | F5: 119 | G5: 15 | H5: 14 | I5: 26 | J5: 23 | K5: 50 | L5: 58 | M5: 0 | N5: 0 | O5: =IF(F5>E5,1,0) | P5: =F5-E5
A6: 0022500004 | B6: 45952 | C6: SAS | D6: DAL | E6: 125 | F6: 92 | G6: 15 | H6: 16 | I6: 25 | J6: 24 | K6: 60 | L6: 47 | M6: 0 | N6: 0 | O6: =IF(F6>E6,1,0) | P6: =F6-E6
A7: 0022500080 | B7: 45952 | C7: BKN | D7: CHA | E7: 117 | F7: 136 | G7: 17 | H7: 17 | I7: 29 | J7: 25 | K7: 44 | L7: 67 | M7: 0 | N7: 0 | O7: =IF(F7>E7,1,0) | P7: =F7-E7
A8: 0022500081 | B8: 45952 | C8: MIA | D8: ORL | E8: 121 | F8: 125 | G8: 19 | H8: 15 | I8: 28 | J8: 20 | K8: 56 | L8: 54 | M8: 0 | N8: 0 | O8: =IF(F8>E8,1,0) | P8: =F8-E8
A9: 0022500082 | B9: 45952 | C9: TOR | D9: ATL | E9: 138 | F9: 118 | G9: 19 | H9: 16 | I9: 32 | J9: 24 | K9: 60 | L9: 44 | M9: 0 | N9: 0 | O9: =IF(F9>E9,1,0) | P9: =F9-E9
A10: 0022500083 | B10: 45952 | C10: PHI | D10: BOS | E10: 117 | F10: 116 | G10: 14 | H10: 11 | I10: 23 | J10: 28 | K10: 55 | L10: 51 | M10: 0 | N10: 0 | O10: =IF(F10>E10,1,0) | P10: =F10-E10
A11: 0022500084 | B11: 45952 | C11: DET | D11: CHI | E11: 111 | F11: 115 | G11: 10 | H11: 18 | I11: 29 | J11: 23 | K11: 56 | L11: 60 | M11: 0 | N11: 0 | O11: =IF(F11>E11,1,0) | P11: =F11-E11
A12: 0022500085 | B12: 45952 | C12: NOP | D12: MEM | E12: 122 | F12: 128 | G12: 15 | H12: 17 | I12: 30 | J12: 29 | K12: 58 | L12: 53 | M12: 0 | N12: 0 | O12: =IF(F12>E12,1,0) | P12: =F12-E12
A13: 0022500086 | B13: 45952 | C13: WAS | D13: MIL | E13: 120 | F13: 133 | G13: 13 | H13: 8 | I13: 19 | J13: 22 | K13: 63 | L13: 50 | M13: 0 | N13: 0 | O13: =IF(F13>E13,1,0) | P13: =F13-E13
A14: 0022500087 | B14: 45952 | C14: LAC | D14: UTA | E14: 108 | F14: 129 | G14: 15 | H14: 13 | I14: 21 | J14: 22 | K14: 45 | L14: 52 | M14: 0 | N14: 0 | O14: =IF(F14>E14,1,0) | P14: =F14-E14
... A1232: 0022501200 | B1232: 46124 | C1232: SAC | D1232: POR | E1232: 110 | F1232: 122 | G1232: 17 | H1232: 12 | I1232: 18 | J1232: 21 | K1232: 55 | L1232: 53 | M1232: 22 | N1232: 41 | O1232: =IF(F1232>E1232,1,0) | P1232: =F1232-E1232

Sheet 2_Params
A1: ARCHITECTURE PARAMETERS — provenance: artifacts/selected_spec.json (Elo-only champion, architecture "conservative"). Fields below the Elo block parameterize the rejected challenger blend only.
A3: parameter | B3: value | C3: where this number is set (file in the GitHub repo — the answer to "where did this come from?")
A4: initial Elo rating | B4: 1500 | C4: code: nba_wp/features.py — every team starts the season rated 1500
A5: Elo K-factor | B5: 7.5 | C5: spec: artifacts/selected_spec.json, field elo_k — rating points that swing on a single game
A6: Elo home-court advantage (pts) | B6: 55 | C6: spec: artifacts/selected_spec.json, field elo_hfa — rating points credited to the home team before each game
A7: Elo logistic scale | B7: 400 | C7: code: nba_wp/features.py — the standard Elo curve, win chance = 1/(1+10^(−diff/400))
A8: MOV multiplier base | B8: 2.2 | C8: code: nba_wp/features.py, _elo_multiplier — margin-of-victory multiplier = ln(|margin|+1) × 2.2 / denominator
A9: MOV denominator slope | B9: 0.001 | C9: code: nba_wp/features.py, _elo_multiplier — denominator = 0.001×(rating gap) + 2.2, so blowouts by favorites count less
A10: MOV denominator floor | B10: 0.25 | C10: code: nba_wp/features.py, _elo_multiplier — denominator never drops below 0.25 (safety guard)
A11: Bradley-Terry C (inverse L2) | B11: 0.1 | C11: spec: artifacts/selected_spec.json, field bt_c — regularization strength of the Bradley-Terry team-strength fit
A12: trend EWMA half-life (days) | B12: 60 | C12: spec: artifacts/selected_spec.json, field trend_half_life_days — a margin from 45 days ago gets half weight in the EWMA
A13: trend short window (games) | B13: 12 | C13: spec: artifacts/selected_spec.json, field trend_short_games — "recent form" = average margin of the last 10 games
A14: elo model C | B14: 10 | C14: spec: artifacts/selected_spec.json, field elo_model_c — regularization of the Elo logistic base model (100 = light)
A15: rank model C | B15: 0.1 | C15: spec: artifacts/selected_spec.json, field rank_model_c — regularization of the rank base model (0.1 = strong)
... A17: logit clip epsilon | B17: 1e-09 | C17: code: nba_wp/model.py, logit() — probabilities clipped away from 0/1 before taking log-odds
A19: Every formula in this workbook references these cells — nothing re-types a constant. Change K to 20 and watch 1,230 ratings, five fitted models, and all April probabilities re-derive.

Sheet 3_Elo_Chain
A1: SEQUENTIAL ELO CHAIN — one row per game, in the repo's exact order (date, then game_id) | H1: reconciliation vs outputs/engineered_features.csv → | J1: max |elo_diff delta|: | K1: =MAX(N3:N1232)
A2: game_id | B2: date | C2: home | D2: away | E2: margin | F2: R_home pre | G2: R_away pre | H2: elo_diff | I2: exp_home | J2: MOV mult | K2: delta | L2: home_win | M2: elo_diff (repo) | N2: |delta|
A3: ='1_Raw_Games'!A3 | B3: ='1_Raw_Games'!B3 | C3: ='1_Raw_Games'!D3 | D3: ='1_Raw_Games'!C3 | E3: ='1_Raw_Games'!P3 | F3: ='2_Params'!$B$4 | G3: ='2_Params'!$B$4 | H3: =(F3-G3+'2_Params'!$B$6)/'2_Params'!$B$7 | I3: =1/(1+10^(-H3)) | J3: =LN(ABS(E3)+1)*('2_Params'!$B$8/MAX('2_Params'!$B$10,(IF(L3=1,F3-G3,G3-F3))*'2_Params'!$B$9+'2_Params'!$B$8)) | K3: ='2_Params'!$B$5*J3*(L3-I3) | L3: ='1_Raw_Games'!O3 | M3: 0.1375 | N3: =ABS(H3-M3)
A4: ='1_Raw_Games'!A4 | B4: ='1_Raw_Games'!B4 | C4: ='1_Raw_Games'!D4 | D4: ='1_Raw_Games'!C4 | E4: ='1_Raw_Games'!P4 | F4: ='2_Params'!$B$4+SUMPRODUCT(($C$3:C3=C4)*($K$3:K3))-SUMPRODUCT(($D$3:D3=C4)*($K$3:K3)) | G4: ='2_Params'!$B$4+SUMPRODUCT(($C$3:C3=D4)*($K$3:K3))-SUMPRODUCT(($D$3:D3=D4)*($K$3:K3)) | H4: =(F4-G4+'2_Params'!$B$6)/'2_Params'!$B$7 | I4: =1/(1+10^(-H4)) | J4: =LN(ABS(E4)+1)*('2_Params'!$B$8/MAX('2_Params'!$B$10,(IF(L4=1,F4-G4,G4-F4))*'2_Params'!$B$9+'2_Params'!$B$8)) | K4: ='2_Params'!$B$5*J4*(L4-I4) | L4: ='1_Raw_Games'!O4 | M4: 0.1375 | N4: =ABS(H4-M4)
A5: ='1_Raw_Games'!A5 | B5: ='1_Raw_Games'!B5 | C5: ='1_Raw_Games'!D5 | D5: ='1_Raw_Games'!C5 | E5: ='1_Raw_Games'!P5 | F5: ='2_Params'!$B$4+SUMPRODUCT(($C$3:C4=C5)*($K$3:K4))-SUMPRODUCT(($D$3:D4=C5)*($K$3:K4)) | G5: ='2_Params'!$B$4+SUMPRODUCT(($C$3:C4=D5)*($K$3:K4))-SUMPRODUCT(($D$3:D4=D5)*($K$3:K4)) | H5: =(F5-G5+'2_Params'!$B$6)/'2_Params'!$B$7 | I5: =1/(1+10^(-H5)) | J5: =LN(ABS(E5)+1)*('2_Params'!$B$8/MAX('2_Params'!$B$10,(IF(L5=1,F5-G5,G5-F5))*'2_Params'!$B$9+'2_Params'!$B$8)) | K5: ='2_Params'!$B$5*J5*(L5-I5) | L5: ='1_Raw_Games'!O5 | M5: 0.1375 | N5: =ABS(H5-M5)
A6: ='1_Raw_Games'!A6 | B6: ='1_Raw_Games'!B6 | C6: ='1_Raw_Games'!D6 | D6: ='1_Raw_Games'!C6 | E6: ='1_Raw_Games'!P6 | F6: ='2_Params'!$B$4+SUMPRODUCT(($C$3:C5=C6)*($K$3:K5))-SUMPRODUCT(($D$3:D5=C6)*($K$3:K5)) | G6: ='2_Params'!$B$4+SUMPRODUCT(($C$3:C5=D6)*($K$3:K5))-SUMPRODUCT(($D$3:D5=D6)*($K$3:K5)) | H6: =(F6-G6+'2_Params'!$B$6)/'2_Params'!$B$7 | I6: =1/(1+10^(-H6)) | J6: =LN(ABS(E6)+1)*('2_Params'!$B$8/MAX('2_Params'!$B$10,(IF(L6=1,F6-G6,G6-F6))*'2_Params'!$B$9+'2_Params'!$B$8)) | K6: ='2_Params'!$B$5*J6*(L6-I6) | L6: ='1_Raw_Games'!O6 | M6: 0.1375 | N6: =ABS(H6-M6)
A7: ='1_Raw_Games'!A7 | B7: ='1_Raw_Games'!B7 | C7: ='1_Raw_Games'!D7 | D7: ='1_Raw_Games'!C7 | E7: ='1_Raw_Games'!P7 | F7: ='2_Params'!$B$4+SUMPRODUCT(($C$3:C6=C7)*($K$3:K6))-SUMPRODUCT(($D$3:D6=C7)*($K$3:K6)) | G7: ='2_Params'!$B$4+SUMPRODUCT(($C$3:C6=D7)*($K$3:K6))-SUMPRODUCT(($D$3:D6=D7)*($K$3:K6)) | H7: =(F7-G7+'2_Params'!$B$6)/'2_Params'!$B$7 | I7: =1/(1+10^(-H7)) | J7: =LN(ABS(E7)+1)*('2_Params'!$B$8/MAX('2_Params'!$B$10,(IF(L7=1,F7-G7,G7-F7))*'2_Params'!$B$9+'2_Params'!$B$8)) | K7: ='2_Params'!$B$5*J7*(L7-I7) | L7: ='1_Raw_Games'!O7 | M7: 0.1375 | N7: =ABS(H7-M7)
A8: ='1_Raw_Games'!A8 | B8: ='1_Raw_Games'!B8 | C8: ='1_Raw_Games'!D8 | D8: ='1_Raw_Games'!C8 | E8: ='1_Raw_Games'!P8 | F8: ='2_Params'!$B$4+SUMPRODUCT(($C$3:C7=C8)*($K$3:K7))-SUMPRODUCT(($D$3:D7=C8)*($K$3:K7)) | G8: ='2_Params'!$B$4+SUMPRODUCT(($C$3:C7=D8)*($K$3:K7))-SUMPRODUCT(($D$3:D7=D8)*($K$3:K7)) | H8: =(F8-G8+'2_Params'!$B$6)/'2_Params'!$B$7 | I8: =1/(1+10^(-H8)) | J8: =LN(ABS(E8)+1)*('2_Params'!$B$8/MAX('2_Params'!$B$10,(IF(L8=1,F8-G8,G8-F8))*'2_Params'!$B$9+'2_Params'!$B$8)) | K8: ='2_Params'!$B$5*J8*(L8-I8) | L8: ='1_Raw_Games'!O8 | M8: 0.1375 | N8: =ABS(H8-M8)
A9: ='1_Raw_Games'!A9 | B9: ='1_Raw_Games'!B9 | C9: ='1_Raw_Games'!D9 | D9: ='1_Raw_Games'!C9 | E9: ='1_Raw_Games'!P9 | F9: ='2_Params'!$B$4+SUMPRODUCT(($C$3:C8=C9)*($K$3:K8))-SUMPRODUCT(($D$3:D8=C9)*($K$3:K8)) | G9: ='2_Params'!$B$4+SUMPRODUCT(($C$3:C8=D9)*($K$3:K8))-SUMPRODUCT(($D$3:D8=D9)*($K$3:K8)) | H9: =(F9-G9+'2_Params'!$B$6)/'2_Params'!$B$7 | I9: =1/(1+10^(-H9)) | J9: =LN(ABS(E9)+1)*('2_Params'!$B$8/MAX('2_Params'!$B$10,(IF(L9=1,F9-G9,G9-F9))*'2_Params'!$B$9+'2_Params'!$B$8)) | K9: ='2_Params'!$B$5*J9*(L9-I9) | L9: ='1_Raw_Games'!O9 | M9: 0.1375 | N9: =ABS(H9-M9)
A10: ='1_Raw_Games'!A10 | B10: ='1_Raw_Games'!B10 | C10: ='1_Raw_Games'!D10 | D10: ='1_Raw_Games'!C10 | E10: ='1_Raw_Games'!P10 | F10: ='2_Params'!$B$4+SUMPRODUCT(($C$3:C9=C10)*($K$3:K9))-SUMPRODUCT(($D$3:D9=C10)*($K$3:K9)) | G10: ='2_Params'!$B$4+SUMPRODUCT(($C$3:C9=D10)*($K$3:K9))-SUMPRODUCT(($D$3:D9=D10)*($K$3:K9)) | H10: =(F10-G10+'2_Params'!$B$6)/'2_Params'!$B$7 | I10: =1/(1+10^(-H10)) | J10: =LN(ABS(E10)+1)*('2_Params'!$B$8/MAX('2_Params'!$B$10,(IF(L10=1,F10-G10,G10-F10))*'2_Params'!$B$9+'2_Params'!$B$8)) | K10: ='2_Params'!$B$5*J10*(L10-I10) | L10: ='1_Raw_Games'!O10 | M10: 0.1375 | N10: =ABS(H10-M10)
A11: ='1_Raw_Games'!A11 | B11: ='1_Raw_Games'!B11 | C11: ='1_Raw_Games'!D11 | D11: ='1_Raw_Games'!C11 | E11: ='1_Raw_Games'!P11 | F11: ='2_Params'!$B$4+SUMPRODUCT(($C$3:C10=C11)*($K$3:K10))-SUMPRODUCT(($D$3:D10=C11)*($K$3:K10)) | G11: ='2_Params'!$B$4+SUMPRODUCT(($C$3:C10=D11)*($K$3:K10))-SUMPRODUCT(($D$3:D10=D11)*($K$3:K10)) | H11: =(F11-G11+'2_Params'!$B$6)/'2_Params'!$B$7 | I11: =1/(1+10^(-H11)) | J11: =LN(ABS(E11)+1)*('2_Params'!$B$8/MAX('2_Params'!$B$10,(IF(L11=1,F11-G11,G11-F11))*'2_Params'!$B$9+'2_Params'!$B$8)) | K11: ='2_Params'!$B$5*J11*(L11-I11) | L11: ='1_Raw_Games'!O11 | M11: 0.1375 | N11: =ABS(H11-M11)
A12: ='1_Raw_Games'!A12 | B12: ='1_Raw_Games'!B12 | C12: ='1_Raw_Games'!D12 | D12: ='1_Raw_Games'!C12 | E12: ='1_Raw_Games'!P12 | F12: ='2_Params'!$B$4+SUMPRODUCT(($C$3:C11=C12)*($K$3:K11))-SUMPRODUCT(($D$3:D11=C12)*($K$3:K11)) | G12: ='2_Params'!$B$4+SUMPRODUCT(($C$3:C11=D12)*($K$3:K11))-SUMPRODUCT(($D$3:D11=D12)*($K$3:K11)) | H12: =(F12-G12+'2_Params'!$B$6)/'2_Params'!$B$7 | I12: =1/(1+10^(-H12)) | J12: =LN(ABS(E12)+1)*('2_Params'!$B$8/MAX('2_Params'!$B$10,(IF(L12=1,F12-G12,G12-F12))*'2_Params'!$B$9+'2_Params'!$B$8)) | K12: ='2_Params'!$B$5*J12*(L12-I12) | L12: ='1_Raw_Games'!O12 | M12: 0.1375 | N12: =ABS(H12-M12)
A13: ='1_Raw_Games'!A13 | B13: ='1_Raw_Games'!B13 | C13: ='1_Raw_Games'!D13 | D13: ='1_Raw_Games'!C13 | E13: ='1_Raw_Games'!P13 | F13: ='2_Params'!$B$4+SUMPRODUCT(($C$3:C12=C13)*($K$3:K12))-SUMPRODUCT(($D$3:D12=C13)*($K$3:K12)) | G13: ='2_Params'!$B$4+SUMPRODUCT(($C$3:C12=D13)*($K$3:K12))-SUMPRODUCT(($D$3:D12=D13)*($K$3:K12)) | H13: =(F13-G13+'2_Params'!$B$6)/'2_Params'!$B$7 | I13: =1/(1+10^(-H13)) | J13: =LN(ABS(E13)+1)*('2_Params'!$B$8/MAX('2_Params'!$B$10,(IF(L13=1,F13-G13,G13-F13))*'2_Params'!$B$9+'2_Params'!$B$8)) | K13: ='2_Params'!$B$5*J13*(L13-I13) | L13: ='1_Raw_Games'!O13 | M13: 0.1375 | N13: =ABS(H13-M13)
A14: ='1_Raw_Games'!A14 | B14: ='1_Raw_Games'!B14 | C14: ='1_Raw_Games'!D14 | D14: ='1_Raw_Games'!C14 | E14: ='1_Raw_Games'!P14 | F14: ='2_Params'!$B$4+SUMPRODUCT(($C$3:C13=C14)*($K$3:K13))-SUMPRODUCT(($D$3:D13=C14)*($K$3:K13)) | G14: ='2_Params'!$B$4+SUMPRODUCT(($C$3:C13=D14)*($K$3:K13))-SUMPRODUCT(($D$3:D13=D14)*($K$3:K13)) | H14: =(F14-G14+'2_Params'!$B$6)/'2_Params'!$B$7 | I14: =1/(1+10^(-H14)) | J14: =LN(ABS(E14)+1)*('2_Params'!$B$8/MAX('2_Params'!$B$10,(IF(L14=1,F14-G14,G14-F14))*'2_Params'!$B$9+'2_Params'!$B$8)) | K14: ='2_Params'!$B$5*J14*(L14-I14) | L14: ='1_Raw_Games'!O14 | M14: 0.1375 | N14: =ABS(H14-M14)
A15: ='1_Raw_Games'!A15 | B15: ='1_Raw_Games'!B15 | C15: ='1_Raw_Games'!D15 | D15: ='1_Raw_Games'!C15 | E15: ='1_Raw_Games'!P15 | F15: ='2_Params'!$B$4+SUMPRODUCT(($C$3:C14=C15)*($K$3:K14))-SUMPRODUCT(($D$3:D14=C15)*($K$3:K14)) | G15: ='2_Params'!$B$4+SUMPRODUCT(($C$3:C14=D15)*($K$3:K14))-SUMPRODUCT(($D$3:D14=D15)*($K$3:K14)) | H15: =(F15-G15+'2_Params'!$B$6)/'2_Params'!$B$7 | I15: =1/(1+10^(-H15)) | J15: =LN(ABS(E15)+1)*('2_Params'!$B$8/MAX('2_Params'!$B$10,(IF(L15=1,F15-G15,G15-F15))*'2_Params'!$B$9+'2_Params'!$B$8)) | K15: ='2_Params'!$B$5*J15*(L15-I15) | L15: ='1_Raw_Games'!O15 | M15: 0.1375 | N15: =ABS(H15-M15)
... A1232: ='1_Raw_Games'!A1232 | B1232: ='1_Raw_Games'!B1232 | C1232: ='1_Raw_Games'!D1232 | D1232: ='1_Raw_Games'!C1232 | E1232: ='1_Raw_Games'!P1232 | F1232: ='2_Params'!$B$4+SUMPRODUCT(($C$3:C1231=C1232)*($K$3:K1231))-SUMPRODUCT(($D$3:D1231=C1232)*($K$3:K1231)) | G1232: ='2_Params'!$B$4+SUMPRODUCT(($C$3:C1231=D1232)*($K$3:K1231))-SUMPRODUCT(($D$3:D1231=D1232)*($K$3:K1231)) | H1232: =(F1232-G1232+'2_Params'!$B$6)/'2_Params'!$B$7 | I1232: =1/(1+10^(-H1232)) | J1232: =LN(ABS(E1232)+1)*('2_Params'!$B$8/MAX('2_Params'!$B$10,(IF(L1232=1,F1232-G1232,G1232-F1232))*'2_Params'!$B$9+'2_Params'!$B$8)) | K1232: ='2_Params'!$B$5*J1232*(L1232-I1232) | L1232: ='1_Raw_Games'!O1232 | M1232: 0.56446729 | N1232: =ABS(H1232-M1232)

Sheet 4_Seq_Features
A1: SEASON FEATURE TABLE (sequential policy) — fitting substrate for sheets 7–9
A2: game_id | B2: date | C2: home | D2: away | E2: home_win | F2: elo_diff | G2: bt_logit | H2: trend_diff | I2: window
A3: ='1_Raw_Games'!A3 | B3: ='1_Raw_Games'!B3 | C3: ='1_Raw_Games'!D3 | D3: ='1_Raw_Games'!C3 | E3: ='1_Raw_Games'!O3 | F3: ='3_Elo_Chain'!H3 | G3: 0 | H3: 0 | I3: train
A4: ='1_Raw_Games'!A4 | B4: ='1_Raw_Games'!B4 | C4: ='1_Raw_Games'!D4 | D4: ='1_Raw_Games'!C4 | E4: ='1_Raw_Games'!O4 | F4: ='3_Elo_Chain'!H4 | G4: 0 | H4: 0 | I4: train
A5: ='1_Raw_Games'!A5 | B5: ='1_Raw_Games'!B5 | C5: ='1_Raw_Games'!D5 | D5: ='1_Raw_Games'!C5 | E5: ='1_Raw_Games'!O5 | F5: ='3_Elo_Chain'!H5 | G5: 0 | H5: 0 | I5: train
A6: ='1_Raw_Games'!A6 | B6: ='1_Raw_Games'!B6 | C6: ='1_Raw_Games'!D6 | D6: ='1_Raw_Games'!C6 | E6: ='1_Raw_Games'!O6 | F6: ='3_Elo_Chain'!H6 | G6: 0 | H6: 0 | I6: train
A7: ='1_Raw_Games'!A7 | B7: ='1_Raw_Games'!B7 | C7: ='1_Raw_Games'!D7 | D7: ='1_Raw_Games'!C7 | E7: ='1_Raw_Games'!O7 | F7: ='3_Elo_Chain'!H7 | G7: 0 | H7: 0 | I7: train
A8: ='1_Raw_Games'!A8 | B8: ='1_Raw_Games'!B8 | C8: ='1_Raw_Games'!D8 | D8: ='1_Raw_Games'!C8 | E8: ='1_Raw_Games'!O8 | F8: ='3_Elo_Chain'!H8 | G8: 0 | H8: 0 | I8: train
A9: ='1_Raw_Games'!A9 | B9: ='1_Raw_Games'!B9 | C9: ='1_Raw_Games'!D9 | D9: ='1_Raw_Games'!C9 | E9: ='1_Raw_Games'!O9 | F9: ='3_Elo_Chain'!H9 | G9: 0 | H9: 0 | I9: train
A10: ='1_Raw_Games'!A10 | B10: ='1_Raw_Games'!B10 | C10: ='1_Raw_Games'!D10 | D10: ='1_Raw_Games'!C10 | E10: ='1_Raw_Games'!O10 | F10: ='3_Elo_Chain'!H10 | G10: 0 | H10: 0 | I10: train
A11: ='1_Raw_Games'!A11 | B11: ='1_Raw_Games'!B11 | C11: ='1_Raw_Games'!D11 | D11: ='1_Raw_Games'!C11 | E11: ='1_Raw_Games'!O11 | F11: ='3_Elo_Chain'!H11 | G11: 0 | H11: 0 | I11: train
A12: ='1_Raw_Games'!A12 | B12: ='1_Raw_Games'!B12 | C12: ='1_Raw_Games'!D12 | D12: ='1_Raw_Games'!C12 | E12: ='1_Raw_Games'!O12 | F12: ='3_Elo_Chain'!H12 | G12: 0 | H12: 0 | I12: train
A13: ='1_Raw_Games'!A13 | B13: ='1_Raw_Games'!B13 | C13: ='1_Raw_Games'!D13 | D13: ='1_Raw_Games'!C13 | E13: ='1_Raw_Games'!O13 | F13: ='3_Elo_Chain'!H13 | G13: 0 | H13: 0 | I13: train
A14: ='1_Raw_Games'!A14 | B14: ='1_Raw_Games'!B14 | C14: ='1_Raw_Games'!D14 | D14: ='1_Raw_Games'!C14 | E14: ='1_Raw_Games'!O14 | F14: ='3_Elo_Chain'!H14 | G14: 0 | H14: 0 | I14: train
... A1232: ='1_Raw_Games'!A1232 | B1232: ='1_Raw_Games'!B1232 | C1232: ='1_Raw_Games'!D1232 | D1232: ='1_Raw_Games'!C1232 | E1232: ='1_Raw_Games'!O1232 | F1232: ='3_Elo_Chain'!H1232 | G1232: 0.89110611 | H1232: 10.027697 | I1232: april

Sheet 5_BT_Frozen
A1: BRADLEY-TERRY, FROZEN AT MARCH 31 — the single fit that prices April (features.py _fit_bradley_terry)
A2: Model: P(home win) = sigmoid(s_home − s_away + b0), coefficients minimizing 0.5·Σs² + C·Σ ln(1+e^(−y·f)) with C = 0.15, y = ±1 (sklearn LogisticRegression parameterization, intercept unpenalized).
A3: Coefficients below were produced by this exact optimization (reproduce live: Data → Solver → minimize objective cell N4 by changing L6:L36, GRG Nonlinear). The gradient block proves optimality on-sheet: all 31 partials ~ 0. | K3: penalized objective (Solver target):
K4: value → minimize by changing L6:L36: | N4: =0.5*SUMPRODUCT($L$6:$L$35,$L$6:$L$35)+SUM($I$6:$I$1139)
A5: game_id | B5: date | C5: home | D5: away | E5: home_win | F5: s_home | G5: s_away | H5: f = sh−sa+b0 | I5: C·ln(1+e^−yf) | K5: team | L5: strength s | M5: ∂obj/∂s (≈0) | N5: check
A6: ='1_Raw_Games'!A3 | B6: ='1_Raw_Games'!B3 | C6: ='1_Raw_Games'!D3 | D6: ='1_Raw_Games'!C3 | E6: ='1_Raw_Games'!O3 | F6: =INDEX($L$6:$L$35,MATCH(C6,$K$6:$K$35,0)) | G6: =INDEX($L$6:$L$35,MATCH(D6,$K$6:$K$35,0)) | H6: =F6-G6+$L$36 | I6: ='2_Params'!$B$11*LN(1+EXP(-(2*E6-1)*H6)) | K6: ATL | L6: 0.19265095 | M6: =L6+'2_Params'!$B$11*(SUMPRODUCT(($C$6:$C$1139=K6)*(1/(1+EXP(-$H$6:$H$1139))-$E$6:$E$1139))-SUMPRODUCT(($D$6:$D$1139=K6)*(1/(1+EXP(-$H$6:$H$1139))-$E$6:$E$1139))) | N6: =IF(ABS(M6)<0.000001,"OK","!!")
A7: ='1_Raw_Games'!A4 | B7: ='1_Raw_Games'!B4 | C7: ='1_Raw_Games'!D4 | D7: ='1_Raw_Games'!C4 | E7: ='1_Raw_Games'!O4 | F7: =INDEX($L$6:$L$35,MATCH(C7,$K$6:$K$35,0)) | G7: =INDEX($L$6:$L$35,MATCH(D7,$K$6:$K$35,0)) | H7: =F7-G7+$L$36 | I7: ='2_Params'!$B$11*LN(1+EXP(-(2*E7-1)*H7)) | K7: BKN | L7: -0.80292006 | M7: =L7+'2_Params'!$B$11*(SUMPRODUCT(($C$6:$C$1139=K7)*(1/(1+EXP(-$H$6:$H$1139))-$E$6:$E$1139))-SUMPRODUCT(($D$6:$D$1139=K7)*(1/(1+EXP(-$H$6:$H$1139))-$E$6:$E$1139))) | N7: =IF(ABS(M7)<0.000001,"OK","!!")
A8: ='1_Raw_Games'!A5 | B8: ='1_Raw_Games'!B5 | C8: ='1_Raw_Games'!D5 | D8: ='1_Raw_Games'!C5 | E8: ='1_Raw_Games'!O5 | F8: =INDEX($L$6:$L$35,MATCH(C8,$K$6:$K$35,0)) | G8: =INDEX($L$6:$L$35,MATCH(D8,$K$6:$K$35,0)) | H8: =F8-G8+$L$36 | I8: ='2_Params'!$B$11*LN(1+EXP(-(2*E8-1)*H8)) | K8: BOS | L8: 0.50921616 | M8: =L8+'2_Params'!$B$11*(SUMPRODUCT(($C$6:$C$1139=K8)*(1/(1+EXP(-$H$6:$H$1139))-$E$6:$E$1139))-SUMPRODUCT(($D$6:$D$1139=K8)*(1/(1+EXP(-$H$6:$H$1139))-$E$6:$E$1139))) | N8: =IF(ABS(M8)<0.000001,"OK","!!")
A9: ='1_Raw_Games'!A6 | B9: ='1_Raw_Games'!B6 | C9: ='1_Raw_Games'!D6 | D9: ='1_Raw_Games'!C6 | E9: ='1_Raw_Games'!O6 | F9: =INDEX($L$6:$L$35,MATCH(C9,$K$6:$K$35,0)) | G9: =INDEX($L$6:$L$35,MATCH(D9,$K$6:$K$35,0)) | H9: =F9-G9+$L$36 | I9: ='2_Params'!$B$11*LN(1+EXP(-(2*E9-1)*H9)) | K9: CHA | L9: 0.055573458 | M9: =L9+'2_Params'!$B$11*(SUMPRODUCT(($C$6:$C$1139=K9)*(1/(1+EXP(-$H$6:$H$1139))-$E$6:$E$1139))-SUMPRODUCT(($D$6:$D$1139=K9)*(1/(1+EXP(-$H$6:$H$1139))-$E$6:$E$1139))) | N9: =IF(ABS(M9)<0.000001,"OK","!!")
A10: ='1_Raw_Games'!A7 | B10: ='1_Raw_Games'!B7 | C10: ='1_Raw_Games'!D7 | D10: ='1_Raw_Games'!C7 | E10: ='1_Raw_Games'!O7 | F10: =INDEX($L$6:$L$35,MATCH(C10,$K$6:$K$35,0)) | G10: =INDEX($L$6:$L$35,MATCH(D10,$K$6:$K$35,0)) | H10: =F10-G10+$L$36 | I10: ='2_Params'!$B$11*LN(1+EXP(-(2*E10-1)*H10)) | K10: CHI | L10: -0.33272647 | M10: =L10+'2_Params'!$B$11*(SUMPRODUCT(($C$6:$C$1139=K10)*(1/(1+EXP(-$H$6:$H$1139))-$E$6:$E$1139))-SUMPRODUCT(($D$6:$D$1139=K10)*(1/(1+EXP(-$H$6:$H$1139))-$E$6:$E$1139))) | N10: =IF(ABS(M10)<0.000001,"OK","!!")
A11: ='1_Raw_Games'!A8 | B11: ='1_Raw_Games'!B8 | C11: ='1_Raw_Games'!D8 | D11: ='1_Raw_Games'!C8 | E11: ='1_Raw_Games'!O8 | F11: =INDEX($L$6:$L$35,MATCH(C11,$K$6:$K$35,0)) | G11: =INDEX($L$6:$L$35,MATCH(D11,$K$6:$K$35,0)) | H11: =F11-G11+$L$36 | I11: ='2_Params'!$B$11*LN(1+EXP(-(2*E11-1)*H11)) | K11: CLE | L11: 0.36426551 | M11: =L11+'2_Params'!$B$11*(SUMPRODUCT(($C$6:$C$1139=K11)*(1/(1+EXP(-$H$6:$H$1139))-$E$6:$E$1139))-SUMPRODUCT(($D$6:$D$1139=K11)*(1/(1+EXP(-$H$6:$H$1139))-$E$6:$E$1139))) | N11: =IF(ABS(M11)<0.000001,"OK","!!")
A12: ='1_Raw_Games'!A9 | B12: ='1_Raw_Games'!B9 | C12: ='1_Raw_Games'!D9 | D12: ='1_Raw_Games'!C9 | E12: ='1_Raw_Games'!O9 | F12: =INDEX($L$6:$L$35,MATCH(C12,$K$6:$K$35,0)) | G12: =INDEX($L$6:$L$35,MATCH(D12,$K$6:$K$35,0)) | H12: =F12-G12+$L$36 | I12: ='2_Params'!$B$11*LN(1+EXP(-(2*E12-1)*H12)) | K12: DAL | L12: -0.57580223 | M12: =L12+'2_Params'!$B$11*(SUMPRODUCT(($C$6:$C$1139=K12)*(1/(1+EXP(-$H$6:$H$1139))-$E$6:$E$1139))-SUMPRODUCT(($D$6:$D$1139=K12)*(1/(1+EXP(-$H$6:$H$1139))-$E$6:$E$1139))) | N12: =IF(ABS(M12)<0.000001,"OK","!!")
A13: ='1_Raw_Games'!A10 | B13: ='1_Raw_Games'!B10 | C13: ='1_Raw_Games'!D10 | D13: ='1_Raw_Games'!C10 | E13: ='1_Raw_Games'!O10 | F13: =INDEX($L$6:$L$35,MATCH(C13,$K$6:$K$35,0)) | G13: =INDEX($L$6:$L$35,MATCH(D13,$K$6:$K$35,0)) | H13: =F13-G13+$L$36 | I13: ='2_Params'!$B$11*LN(1+EXP(-(2*E13-1)*H13)) | K13: DEN | L13: 0.39731121 | M13: =L13+'2_Params'!$B$11*(SUMPRODUCT(($C$6:$C$1139=K13)*(1/(1+EXP(-$H$6:$H$1139))-$E$6:$E$1139))-SUMPRODUCT(($D$6:$D$1139=K13)*(1/(1+EXP(-$H$6:$H$1139))-$E$6:$E$1139))) | N13: =IF(ABS(M13)<0.000001,"OK","!!")
A14: ='1_Raw_Games'!A11 | B14: ='1_Raw_Games'!B11 | C14: ='1_Raw_Games'!D11 | D14: ='1_Raw_Games'!C11 | E14: ='1_Raw_Games'!O11 | F14: =INDEX($L$6:$L$35,MATCH(C14,$K$6:$K$35,0)) | G14: =INDEX($L$6:$L$35,MATCH(D14,$K$6:$K$35,0)) | H14: =F14-G14+$L$36 | I14: ='2_Params'!$B$11*LN(1+EXP(-(2*E14-1)*H14)) | K14: DET | L14: 0.67645918 | M14: =L14+'2_Params'!$B$11*(SUMPRODUCT(($C$6:$C$1139=K14)*(1/(1+EXP(-$H$6:$H$1139))-$E$6:$E$1139))-SUMPRODUCT(($D$6:$D$1139=K14)*(1/(1+EXP(-$H$6:$H$1139))-$E$6:$E$1139))) | N14: =IF(ABS(M14)<0.000001,"OK","!!")
A15: ='1_Raw_Games'!A12 | B15: ='1_Raw_Games'!B12 | C15: ='1_Raw_Games'!D12 | D15: ='1_Raw_Games'!C12 | E15: ='1_Raw_Games'!O12 | F15: =INDEX($L$6:$L$35,MATCH(C15,$K$6:$K$35,0)) | G15: =INDEX($L$6:$L$35,MATCH(D15,$K$6:$K$35,0)) | H15: =F15-G15+$L$36 | I15: ='2_Params'!$B$11*LN(1+EXP(-(2*E15-1)*H15)) | K15: GSW | L15: -0.037414766 | M15: =L15+'2_Params'!$B$11*(SUMPRODUCT(($C$6:$C$1139=K15)*(1/(1+EXP(-$H$6:$H$1139))-$E$6:$E$1139))-SUMPRODUCT(($D$6:$D$1139=K15)*(1/(1+EXP(-$H$6:$H$1139))-$E$6:$E$1139))) | N15: =IF(ABS(M15)<0.000001,"OK","!!")
A16: ='1_Raw_Games'!A13 | B16: ='1_Raw_Games'!B13 | C16: ='1_Raw_Games'!D13 | D16: ='1_Raw_Games'!C13 | E16: ='1_Raw_Games'!O13 | F16: =INDEX($L$6:$L$35,MATCH(C16,$K$6:$K$35,0)) | G16: =INDEX($L$6:$L$35,MATCH(D16,$K$6:$K$35,0)) | H16: =F16-G16+$L$36 | I16: ='2_Params'!$B$11*LN(1+EXP(-(2*E16-1)*H16)) | K16: HOU | L16: 0.35019214 | M16: =L16+'2_Params'!$B$11*(SUMPRODUCT(($C$6:$C$1139=K16)*(1/(1+EXP(-$H$6:$H$1139))-$E$6:$E$1139))-SUMPRODUCT(($D$6:$D$1139=K16)*(1/(1+EXP(-$H$6:$H$1139))-$E$6:$E$1139))) | N16: =IF(ABS(M16)<0.000001,"OK","!!")
A17: ='1_Raw_Games'!A14 | B17: ='1_Raw_Games'!B14 | C17: ='1_Raw_Games'!D14 | D17: ='1_Raw_Games'!C14 | E17: ='1_Raw_Games'!O14 | F17: =INDEX($L$6:$L$35,MATCH(C17,$K$6:$K$35,0)) | G17: =INDEX($L$6:$L$35,MATCH(D17,$K$6:$K$35,0)) | H17: =F17-G17+$L$36 | I17: ='2_Params'!$B$11*LN(1+EXP(-(2*E17-1)*H17)) | K17: IND | L17: -0.8562387 | M17: =L17+'2_Params'!$B$11*(SUMPRODUCT(($C$6:$C$1139=K17)*(1/(1+EXP(-$H$6:$H$1139))-$E$6:$E$1139))-SUMPRODUCT(($D$6:$D$1139=K17)*(1/(1+EXP(-$H$6:$H$1139))-$E$6:$E$1139))) | N17: =IF(ABS(M17)<0.000001,"OK","!!")
... A35: ='1_Raw_Games'!A32 | B35: ='1_Raw_Games'!B32 | C35: ='1_Raw_Games'!D32 | D35: ='1_Raw_Games'!C32 | E35: ='1_Raw_Games'!O32 | F35: =INDEX($L$6:$L$35,MATCH(C35,$K$6:$K$35,0)) | G35: =INDEX($L$6:$L$35,MATCH(D35,$K$6:$K$35,0)) | H35: =F35-G35+$L$36 | I35: ='2_Params'!$B$11*LN(1+EXP(-(2*E35-1)*H35)) | K35: WAS | L35: -0.85233857 | M35: =L35+'2_Params'!$B$11*(SUMPRODUCT(($C$6:$C$1139=K35)*(1/(1+EXP(-$H$6:$H$1139))-$E$6:$E$1139))-SUMPRODUCT(($D$6:$D$1139=K35)*(1/(1+EXP(-$H$6:$H$1139))-$E$6:$E$1139))) | N35: =IF(ABS(M35)<0.000001,"OK","!!")
A36: ='1_Raw_Games'!A33 | B36: ='1_Raw_Games'!B33 | C36: ='1_Raw_Games'!D33 | D36: ='1_Raw_Games'!C33 | E36: ='1_Raw_Games'!O33 | F36: =INDEX($L$6:$L$35,MATCH(C36,$K$6:$K$35,0)) | G36: =INDEX($L$6:$L$35,MATCH(D36,$K$6:$K$35,0)) | H36: =F36-G36+$L$36 | I36: ='2_Params'!$B$11*LN(1+EXP(-(2*E36-1)*H36)) | K36: (intercept b0) | L36: 0.23377294 | M36: ='2_Params'!$B$11*SUMPRODUCT(1/(1+EXP(-$H$6:$H$1139))-$E$6:$E$1139) | N36: =IF(ABS(M36)<0.000001,"OK","!!")
A37: ='1_Raw_Games'!A34 | B37: ='1_Raw_Games'!B34 | C37: ='1_Raw_Games'!D34 | D37: ='1_Raw_Games'!C34 | E37: ='1_Raw_Games'!O34 | F37: =INDEX($L$6:$L$35,MATCH(C37,$K$6:$K$35,0)) | G37: =INDEX($L$6:$L$35,MATCH(D37,$K$6:$K$35,0)) | H37: =F37-G37+$L$36 | I37: ='2_Params'!$B$11*LN(1+EXP(-(2*E37-1)*H37))
A38: ='1_Raw_Games'!A35 | B38: ='1_Raw_Games'!B35 | C38: ='1_Raw_Games'!D35 | D38: ='1_Raw_Games'!C35 | E38: ='1_Raw_Games'!O35 | F38: =INDEX($L$6:$L$35,MATCH(C38,$K$6:$K$35,0)) | G38: =INDEX($L$6:$L$35,MATCH(D38,$K$6:$K$35,0)) | H38: =F38-G38+$L$36 | I38: ='2_Params'!$B$11*LN(1+EXP(-(2*E38-1)*H38)) | K38: max |gradient|: | L38: =MAX(ABS(M6),MAX(M6:M36),-MIN(M6:M36))
A39: ='1_Raw_Games'!A36 | B39: ='1_Raw_Games'!B36 | C39: ='1_Raw_Games'!D36 | D39: ='1_Raw_Games'!C36 | E39: ='1_Raw_Games'!O36 | F39: =INDEX($L$6:$L$35,MATCH(C39,$K$6:$K$35,0)) | G39: =INDEX($L$6:$L$35,MATCH(D39,$K$6:$K$35,0)) | H39: =F39-G39+$L$36 | I39: ='2_Params'!$B$11*LN(1+EXP(-(2*E39-1)*H39)) | K39: A zero gradient of a strictly convex objective identifies the unique global optimum — these strengths are proven, not pasted.
A40: ='1_Raw_Games'!A37 | B40: ='1_Raw_Games'!B37 | C40: ='1_Raw_Games'!D37 | D40: ='1_Raw_Games'!C37 | E40: ='1_Raw_Games'!O37 | F40: =INDEX($L$6:$L$35,MATCH(C40,$K$6:$K$35,0)) | G40: =INDEX($L$6:$L$35,MATCH(D40,$K$6:$K$35,0)) | H40: =F40-G40+$L$36 | I40: ='2_Params'!$B$11*LN(1+EXP(-(2*E40-1)*H40))
A41: ='1_Raw_Games'!A38 | B41: ='1_Raw_Games'!B38 | C41: ='1_Raw_Games'!D38 | D41: ='1_Raw_Games'!C38 | E41: ='1_Raw_Games'!O38 | F41: =INDEX($L$6:$L$35,MATCH(C41,$K$6:$K$35,0)) | G41: =INDEX($L$6:$L$35,MATCH(D41,$K$6:$K$35,0)) | H41: =F41-G41+$L$36 | I41: ='2_Params'!$B$11*LN(1+EXP(-(2*E41-1)*H41))
A42: ='1_Raw_Games'!A39 | B42: ='1_Raw_Games'!B39 | C42: ='1_Raw_Games'!D39 | D42: ='1_Raw_Games'!C39 | E42: ='1_Raw_Games'!O39 | F42: =INDEX($L$6:$L$35,MATCH(C42,$K$6:$K$35,0)) | G42: =INDEX($L$6:$L$35,MATCH(D42,$K$6:$K$35,0)) | H42: =F42-G42+$L$36 | I42: ='2_Params'!$B$11*LN(1+EXP(-(2*E42-1)*H42))
A43: ='1_Raw_Games'!A40 | B43: ='1_Raw_Games'!B40 | C43: ='1_Raw_Games'!D40 | D43: ='1_Raw_Games'!C40 | E43: ='1_Raw_Games'!O40 | F43: =INDEX($L$6:$L$35,MATCH(C43,$K$6:$K$35,0)) | G43: =INDEX($L$6:$L$35,MATCH(D43,$K$6:$K$35,0)) | H43: =F43-G43+$L$36 | I43: ='2_Params'!$B$11*LN(1+EXP(-(2*E43-1)*H43))
A44: ='1_Raw_Games'!A41 | B44: ='1_Raw_Games'!B41 | C44: ='1_Raw_Games'!D41 | D44: ='1_Raw_Games'!C41 | E44: ='1_Raw_Games'!O41 | F44: =INDEX($L$6:$L$35,MATCH(C44,$K$6:$K$35,0)) | G44: =INDEX($L$6:$L$35,MATCH(D44,$K$6:$K$35,0)) | H44: =F44-G44+$L$36 | I44: ='2_Params'!$B$11*LN(1+EXP(-(2*E44-1)*H44))
A45: ='1_Raw_Games'!A42 | B45: ='1_Raw_Games'!B42 | C45: ='1_Raw_Games'!D42 | D45: ='1_Raw_Games'!C42 | E45: ='1_Raw_Games'!O42 | F45: =INDEX($L$6:$L$35,MATCH(C45,$K$6:$K$35,0)) | G45: =INDEX($L$6:$L$35,MATCH(D45,$K$6:$K$35,0)) | H45: =F45-G45+$L$36 | I45: ='2_Params'!$B$11*LN(1+EXP(-(2*E45-1)*H45))
A46: ='1_Raw_Games'!A43 | B46: ='1_Raw_Games'!B43 | C46: ='1_Raw_Games'!D43 | D46: ='1_Raw_Games'!C43 | E46: ='1_Raw_Games'!O43 | F46: =INDEX($L$6:$L$35,MATCH(C46,$K$6:$K$35,0)) | G46: =INDEX($L$6:$L$35,MATCH(D46,$K$6:$K$35,0)) | H46: =F46-G46+$L$36 | I46: ='2_Params'!$B$11*LN(1+EXP(-(2*E46-1)*H46))
A47: ='1_Raw_Games'!A44 | B47: ='1_Raw_Games'!B44 | C47: ='1_Raw_Games'!D44 | D47: ='1_Raw_Games'!C44 | E47: ='1_Raw_Games'!O44 | F47: =INDEX($L$6:$L$35,MATCH(C47,$K$6:$K$35,0)) | G47: =INDEX($L$6:$L$35,MATCH(D47,$K$6:$K$35,0)) | H47: =F47-G47+$L$36 | I47: ='2_Params'!$B$11*LN(1+EXP(-(2*E47-1)*H47))
A48: ='1_Raw_Games'!A45 | B48: ='1_Raw_Games'!B45 | C48: ='1_Raw_Games'!D45 | D48: ='1_Raw_Games'!C45 | E48: ='1_Raw_Games'!O45 | F48: =INDEX($L$6:$L$35,MATCH(C48,$K$6:$K$35,0)) | G48: =INDEX($L$6:$L$35,MATCH(D48,$K$6:$K$35,0)) | H48: =F48-G48+$L$36 | I48: ='2_Params'!$B$11*LN(1+EXP(-(2*E48-1)*H48))
A49: ='1_Raw_Games'!A46 | B49: ='1_Raw_Games'!B46 | C49: ='1_Raw_Games'!D46 | D49: ='1_Raw_Games'!C46 | E49: ='1_Raw_Games'!O46 | F49: =INDEX($L$6:$L$35,MATCH(C49,$K$6:$K$35,0)) | G49: =INDEX($L$6:$L$35,MATCH(D49,$K$6:$K$35,0)) | H49: =F49-G49+$L$36 | I49: ='2_Params'!$B$11*LN(1+EXP(-(2*E49-1)*H49))
A50: ='1_Raw_Games'!A47 | B50: ='1_Raw_Games'!B47 | C50: ='1_Raw_Games'!D47 | D50: ='1_Raw_Games'!C47 | E50: ='1_Raw_Games'!O47 | F50: =INDEX($L$6:$L$35,MATCH(C50,$K$6:$K$35,0)) | G50: =INDEX($L$6:$L$35,MATCH(D50,$K$6:$K$35,0)) | H50: =F50-G50+$L$36 | I50: ='2_Params'!$B$11*LN(1+EXP(-(2*E50-1)*H50))
A51: ='1_Raw_Games'!A48 | B51: ='1_Raw_Games'!B48 | C51: ='1_Raw_Games'!D48 | D51: ='1_Raw_Games'!C48 | E51: ='1_Raw_Games'!O48 | F51: =INDEX($L$6:$L$35,MATCH(C51,$K$6:$K$35,0)) | G51: =INDEX($L$6:$L$35,MATCH(D51,$K$6:$K$35,0)) | H51: =F51-G51+$L$36 | I51: ='2_Params'!$B$11*LN(1+EXP(-(2*E51-1)*H51))
... A1139: ='1_Raw_Games'!A1136 | B1139: ='1_Raw_Games'!B1136 | C1139: ='1_Raw_Games'!D1136 | D1139: ='1_Raw_Games'!C1136 | E1139: ='1_Raw_Games'!O1136 | F1139: =INDEX($L$6:$L$35,MATCH(C1139,$K$6:$K$35,0)) | G1139: =INDEX($L$6:$L$35,MATCH(D1139,$K$6:$K$35,0)) | H1139: =F1139-G1139+$L$36 | I1139: ='2_Params'!$B$11*LN(1+EXP(-(2*E1139-1)*H1139))

Sheet 6_Trend_Frozen
A1: TREND, FROZEN AT MARCH 31 — trend = mean(last 10 margins) − EWMA(all margins, half-life 45 days) | G1: APRIL TREND FEATURE (96 games) — reconciled vs outputs/april_predictions_frozen_snapshot.csv
A2: History: every pre-April game twice (home and away perspective). recency_rank = games played after this one; last-10 flag = rank < 10. April lookups on the right use SUMPRODUCT over this table.
A3: team | B3: date | C3: margin | D3: recency rank | E3: in last 10 | G3: game_id | H3: date | I3: home | J3: away | K3: trend_home | L3: trend_away | M3: trend_diff | N3: repo trend_diff | O3: |delta|
A4: ='1_Raw_Games'!D3 | B4: ='1_Raw_Games'!B3 | C4: ='1_Raw_Games'!P3 | D4: =COUNTIFS($A$4:$A$2271,A4,$B$4:$B$2271,">"&B4) | E4: =IF(D4<'2_Params'!$B$13,1,0) | G4: ='1_Raw_Games'!A1137 | H4: ='1_Raw_Games'!B1137 | I4: ='1_Raw_Games'!D1137 | J4: ='1_Raw_Games'!C1137 | K4: =SUMPRODUCT(($A$4:$A$2271=I4)*$E$4:$E$2271*$C$4:$C$2271)/SUMPRODUCT(($A$4:$A$2271=I4)*$E$4:$E$2271)-SUMPRODUCT(($A$4:$A$2271=I4)*0.5^((H4-$B$4:$B$2271)/'2_Params'!$B$12)*$C$4:$C$2271)/SUMPRODUCT(($A$4:$A$2271=I4)*0.5^((H4-$B$4:$B$2271)/'2_Params'!$B$12)) | L4: =SUMPRODUCT(($A$4:$A$2271=J4)*$E$4:$E$2271*$C$4:$C$2271)/SUMPRODUCT(($A$4:$A$2271=J4)*$E$4:$E$2271)-SUMPRODUCT(($A$4:$A$2271=J4)*0.5^((H4-$B$4:$B$2271)/'2_Params'!$B$12)*$C$4:$C$2271)/SUMPRODUCT(($A$4:$A$2271=J4)*0.5^((H4-$B$4:$B$2271)/'2_Params'!$B$12)) | M4: =K4-L4 | N4: -8.3658095 | O4: =ABS(M4-N4)
A5: ='1_Raw_Games'!D4 | B5: ='1_Raw_Games'!B4 | C5: ='1_Raw_Games'!P4 | D5: =COUNTIFS($A$4:$A$2271,A5,$B$4:$B$2271,">"&B5) | E5: =IF(D5<'2_Params'!$B$13,1,0) | G5: ='1_Raw_Games'!A1138 | H5: ='1_Raw_Games'!B1138 | I5: ='1_Raw_Games'!D1138 | J5: ='1_Raw_Games'!C1138 | K5: =SUMPRODUCT(($A$4:$A$2271=I5)*$E$4:$E$2271*$C$4:$C$2271)/SUMPRODUCT(($A$4:$A$2271=I5)*$E$4:$E$2271)-SUMPRODUCT(($A$4:$A$2271=I5)*0.5^((H5-$B$4:$B$2271)/'2_Params'!$B$12)*$C$4:$C$2271)/SUMPRODUCT(($A$4:$A$2271=I5)*0.5^((H5-$B$4:$B$2271)/'2_Params'!$B$12)) | L5: =SUMPRODUCT(($A$4:$A$2271=J5)*$E$4:$E$2271*$C$4:$C$2271)/SUMPRODUCT(($A$4:$A$2271=J5)*$E$4:$E$2271)-SUMPRODUCT(($A$4:$A$2271=J5)*0.5^((H5-$B$4:$B$2271)/'2_Params'!$B$12)*$C$4:$C$2271)/SUMPRODUCT(($A$4:$A$2271=J5)*0.5^((H5-$B$4:$B$2271)/'2_Params'!$B$12)) | M5: =K5-L5 | N5: -2.6365459 | O5: =ABS(M5-N5)
A6: ='1_Raw_Games'!D5 | B6: ='1_Raw_Games'!B5 | C6: ='1_Raw_Games'!P5 | D6: =COUNTIFS($A$4:$A$2271,A6,$B$4:$B$2271,">"&B6) | E6: =IF(D6<'2_Params'!$B$13,1,0) | G6: ='1_Raw_Games'!A1139 | H6: ='1_Raw_Games'!B1139 | I6: ='1_Raw_Games'!D1139 | J6: ='1_Raw_Games'!C1139 | K6: =SUMPRODUCT(($A$4:$A$2271=I6)*$E$4:$E$2271*$C$4:$C$2271)/SUMPRODUCT(($A$4:$A$2271=I6)*$E$4:$E$2271)-SUMPRODUCT(($A$4:$A$2271=I6)*0.5^((H6-$B$4:$B$2271)/'2_Params'!$B$12)*$C$4:$C$2271)/SUMPRODUCT(($A$4:$A$2271=I6)*0.5^((H6-$B$4:$B$2271)/'2_Params'!$B$12)) | L6: =SUMPRODUCT(($A$4:$A$2271=J6)*$E$4:$E$2271*$C$4:$C$2271)/SUMPRODUCT(($A$4:$A$2271=J6)*$E$4:$E$2271)-SUMPRODUCT(($A$4:$A$2271=J6)*0.5^((H6-$B$4:$B$2271)/'2_Params'!$B$12)*$C$4:$C$2271)/SUMPRODUCT(($A$4:$A$2271=J6)*0.5^((H6-$B$4:$B$2271)/'2_Params'!$B$12)) | M6: =K6-L6 | N6: -7.2191736 | O6: =ABS(M6-N6)
A7: ='1_Raw_Games'!D6 | B7: ='1_Raw_Games'!B6 | C7: ='1_Raw_Games'!P6 | D7: =COUNTIFS($A$4:$A$2271,A7,$B$4:$B$2271,">"&B7) | E7: =IF(D7<'2_Params'!$B$13,1,0) | G7: ='1_Raw_Games'!A1140 | H7: ='1_Raw_Games'!B1140 | I7: ='1_Raw_Games'!D1140 | J7: ='1_Raw_Games'!C1140 | K7: =SUMPRODUCT(($A$4:$A$2271=I7)*$E$4:$E$2271*$C$4:$C$2271)/SUMPRODUCT(($A$4:$A$2271=I7)*$E$4:$E$2271)-SUMPRODUCT(($A$4:$A$2271=I7)*0.5^((H7-$B$4:$B$2271)/'2_Params'!$B$12)*$C$4:$C$2271)/SUMPRODUCT(($A$4:$A$2271=I7)*0.5^((H7-$B$4:$B$2271)/'2_Params'!$B$12)) | L7: =SUMPRODUCT(($A$4:$A$2271=J7)*$E$4:$E$2271*$C$4:$C$2271)/SUMPRODUCT(($A$4:$A$2271=J7)*$E$4:$E$2271)-SUMPRODUCT(($A$4:$A$2271=J7)*0.5^((H7-$B$4:$B$2271)/'2_Params'!$B$12)*$C$4:$C$2271)/SUMPRODUCT(($A$4:$A$2271=J7)*0.5^((H7-$B$4:$B$2271)/'2_Params'!$B$12)) | M7: =K7-L7 | N7: -12.399238 | O7: =ABS(M7-N7)
A8: ='1_Raw_Games'!D7 | B8: ='1_Raw_Games'!B7 | C8: ='1_Raw_Games'!P7 | D8: =COUNTIFS($A$4:$A$2271,A8,$B$4:$B$2271,">"&B8) | E8: =IF(D8<'2_Params'!$B$13,1,0) | G8: ='1_Raw_Games'!A1141 | H8: ='1_Raw_Games'!B1141 | I8: ='1_Raw_Games'!D1141 | J8: ='1_Raw_Games'!C1141 | K8: =SUMPRODUCT(($A$4:$A$2271=I8)*$E$4:$E$2271*$C$4:$C$2271)/SUMPRODUCT(($A$4:$A$2271=I8)*$E$4:$E$2271)-SUMPRODUCT(($A$4:$A$2271=I8)*0.5^((H8-$B$4:$B$2271)/'2_Params'!$B$12)*$C$4:$C$2271)/SUMPRODUCT(($A$4:$A$2271=I8)*0.5^((H8-$B$4:$B$2271)/'2_Params'!$B$12)) | L8: =SUMPRODUCT(($A$4:$A$2271=J8)*$E$4:$E$2271*$C$4:$C$2271)/SUMPRODUCT(($A$4:$A$2271=J8)*$E$4:$E$2271)-SUMPRODUCT(($A$4:$A$2271=J8)*0.5^((H8-$B$4:$B$2271)/'2_Params'!$B$12)*$C$4:$C$2271)/SUMPRODUCT(($A$4:$A$2271=J8)*0.5^((H8-$B$4:$B$2271)/'2_Params'!$B$12)) | M8: =K8-L8 | N8: 4.7430735 | O8: =ABS(M8-N8)
A9: ='1_Raw_Games'!D8 | B9: ='1_Raw_Games'!B8 | C9: ='1_Raw_Games'!P8 | D9: =COUNTIFS($A$4:$A$2271,A9,$B$4:$B$2271,">"&B9) | E9: =IF(D9<'2_Params'!$B$13,1,0) | G9: ='1_Raw_Games'!A1142 | H9: ='1_Raw_Games'!B1142 | I9: ='1_Raw_Games'!D1142 | J9: ='1_Raw_Games'!C1142 | K9: =SUMPRODUCT(($A$4:$A$2271=I9)*$E$4:$E$2271*$C$4:$C$2271)/SUMPRODUCT(($A$4:$A$2271=I9)*$E$4:$E$2271)-SUMPRODUCT(($A$4:$A$2271=I9)*0.5^((H9-$B$4:$B$2271)/'2_Params'!$B$12)*$C$4:$C$2271)/SUMPRODUCT(($A$4:$A$2271=I9)*0.5^((H9-$B$4:$B$2271)/'2_Params'!$B$12)) | L9: =SUMPRODUCT(($A$4:$A$2271=J9)*$E$4:$E$2271*$C$4:$C$2271)/SUMPRODUCT(($A$4:$A$2271=J9)*$E$4:$E$2271)-SUMPRODUCT(($A$4:$A$2271=J9)*0.5^((H9-$B$4:$B$2271)/'2_Params'!$B$12)*$C$4:$C$2271)/SUMPRODUCT(($A$4:$A$2271=J9)*0.5^((H9-$B$4:$B$2271)/'2_Params'!$B$12)) | M9: =K9-L9 | N9: -2.9611615 | O9: =ABS(M9-N9)
A10: ='1_Raw_Games'!D9 | B10: ='1_Raw_Games'!B9 | C10: ='1_Raw_Games'!P9 | D10: =COUNTIFS($A$4:$A$2271,A10,$B$4:$B$2271,">"&B10) | E10: =IF(D10<'2_Params'!$B$13,1,0) | G10: ='1_Raw_Games'!A1143 | H10: ='1_Raw_Games'!B1143 | I10: ='1_Raw_Games'!D1143 | J10: ='1_Raw_Games'!C1143 | K10: =SUMPRODUCT(($A$4:$A$2271=I10)*$E$4:$E$2271*$C$4:$C$2271)/SUMPRODUCT(($A$4:$A$2271=I10)*$E$4:$E$2271)-SUMPRODUCT(($A$4:$A$2271=I10)*0.5^((H10-$B$4:$B$2271)/'2_Params'!$B$12)*$C$4:$C$2271)/SUMPRODUCT(($A$4:$A$2271=I10)*0.5^((H10-$B$4:$B$2271)/'2_Params'!$B$12)) | L10: =SUMPRODUCT(($A$4:$A$2271=J10)*$E$4:$E$2271*$C$4:$C$2271)/SUMPRODUCT(($A$4:$A$2271=J10)*$E$4:$E$2271)-SUMPRODUCT(($A$4:$A$2271=J10)*0.5^((H10-$B$4:$B$2271)/'2_Params'!$B$12)*$C$4:$C$2271)/SUMPRODUCT(($A$4:$A$2271=J10)*0.5^((H10-$B$4:$B$2271)/'2_Params'!$B$12)) | M10: =K10-L10 | N10: 7.1379716 | O10: =ABS(M10-N10)
A11: ='1_Raw_Games'!D10 | B11: ='1_Raw_Games'!B10 | C11: ='1_Raw_Games'!P10 | D11: =COUNTIFS($A$4:$A$2271,A11,$B$4:$B$2271,">"&B11) | E11: =IF(D11<'2_Params'!$B$13,1,0) | G11: ='1_Raw_Games'!A1144 | H11: ='1_Raw_Games'!B1144 | I11: ='1_Raw_Games'!D1144 | J11: ='1_Raw_Games'!C1144 | K11: =SUMPRODUCT(($A$4:$A$2271=I11)*$E$4:$E$2271*$C$4:$C$2271)/SUMPRODUCT(($A$4:$A$2271=I11)*$E$4:$E$2271)-SUMPRODUCT(($A$4:$A$2271=I11)*0.5^((H11-$B$4:$B$2271)/'2_Params'!$B$12)*$C$4:$C$2271)/SUMPRODUCT(($A$4:$A$2271=I11)*0.5^((H11-$B$4:$B$2271)/'2_Params'!$B$12)) | L11: =SUMPRODUCT(($A$4:$A$2271=J11)*$E$4:$E$2271*$C$4:$C$2271)/SUMPRODUCT(($A$4:$A$2271=J11)*$E$4:$E$2271)-SUMPRODUCT(($A$4:$A$2271=J11)*0.5^((H11-$B$4:$B$2271)/'2_Params'!$B$12)*$C$4:$C$2271)/SUMPRODUCT(($A$4:$A$2271=J11)*0.5^((H11-$B$4:$B$2271)/'2_Params'!$B$12)) | M11: =K11-L11 | N11: -6.0943169 | O11: =ABS(M11-N11)
A12: ='1_Raw_Games'!D11 | B12: ='1_Raw_Games'!B11 | C12: ='1_Raw_Games'!P11 | D12: =COUNTIFS($A$4:$A$2271,A12,$B$4:$B$2271,">"&B12) | E12: =IF(D12<'2_Params'!$B$13,1,0) | G12: ='1_Raw_Games'!A1145 | H12: ='1_Raw_Games'!B1145 | I12: ='1_Raw_Games'!D1145 | J12: ='1_Raw_Games'!C1145 | K12: =SUMPRODUCT(($A$4:$A$2271=I12)*$E$4:$E$2271*$C$4:$C$2271)/SUMPRODUCT(($A$4:$A$2271=I12)*$E$4:$E$2271)-SUMPRODUCT(($A$4:$A$2271=I12)*0.5^((H12-$B$4:$B$2271)/'2_Params'!$B$12)*$C$4:$C$2271)/SUMPRODUCT(($A$4:$A$2271=I12)*0.5^((H12-$B$4:$B$2271)/'2_Params'!$B$12)) | L12: =SUMPRODUCT(($A$4:$A$2271=J12)*$E$4:$E$2271*$C$4:$C$2271)/SUMPRODUCT(($A$4:$A$2271=J12)*$E$4:$E$2271)-SUMPRODUCT(($A$4:$A$2271=J12)*0.5^((H12-$B$4:$B$2271)/'2_Params'!$B$12)*$C$4:$C$2271)/SUMPRODUCT(($A$4:$A$2271=J12)*0.5^((H12-$B$4:$B$2271)/'2_Params'!$B$12)) | M12: =K12-L12 | N12: -8.5819447 | O12: =ABS(M12-N12)
A13: ='1_Raw_Games'!D12 | B13: ='1_Raw_Games'!B12 | C13: ='1_Raw_Games'!P12 | D13: =COUNTIFS($A$4:$A$2271,A13,$B$4:$B$2271,">"&B13) | E13: =IF(D13<'2_Params'!$B$13,1,0) | G13: ='1_Raw_Games'!A1146 | H13: ='1_Raw_Games'!B1146 | I13: ='1_Raw_Games'!D1146 | J13: ='1_Raw_Games'!C1146 | K13: =SUMPRODUCT(($A$4:$A$2271=I13)*$E$4:$E$2271*$C$4:$C$2271)/SUMPRODUCT(($A$4:$A$2271=I13)*$E$4:$E$2271)-SUMPRODUCT(($A$4:$A$2271=I13)*0.5^((H13-$B$4:$B$2271)/'2_Params'!$B$12)*$C$4:$C$2271)/SUMPRODUCT(($A$4:$A$2271=I13)*0.5^((H13-$B$4:$B$2271)/'2_Params'!$B$12)) | L13: =SUMPRODUCT(($A$4:$A$2271=J13)*$E$4:$E$2271*$C$4:$C$2271)/SUMPRODUCT(($A$4:$A$2271=J13)*$E$4:$E$2271)-SUMPRODUCT(($A$4:$A$2271=J13)*0.5^((H13-$B$4:$B$2271)/'2_Params'!$B$12)*$C$4:$C$2271)/SUMPRODUCT(($A$4:$A$2271=J13)*0.5^((H13-$B$4:$B$2271)/'2_Params'!$B$12)) | M13: =K13-L13 | N13: 3.3632294 | O13: =ABS(M13-N13)
A14: ='1_Raw_Games'!D13 | B14: ='1_Raw_Games'!B13 | C14: ='1_Raw_Games'!P13 | D14: =COUNTIFS($A$4:$A$2271,A14,$B$4:$B$2271,">"&B14) | E14: =IF(D14<'2_Params'!$B$13,1,0) | G14: ='1_Raw_Games'!A1147 | H14: ='1_Raw_Games'!B1147 | I14: ='1_Raw_Games'!D1147 | J14: ='1_Raw_Games'!C1147 | K14: =SUMPRODUCT(($A$4:$A$2271=I14)*$E$4:$E$2271*$C$4:$C$2271)/SUMPRODUCT(($A$4:$A$2271=I14)*$E$4:$E$2271)-SUMPRODUCT(($A$4:$A$2271=I14)*0.5^((H14-$B$4:$B$2271)/'2_Params'!$B$12)*$C$4:$C$2271)/SUMPRODUCT(($A$4:$A$2271=I14)*0.5^((H14-$B$4:$B$2271)/'2_Params'!$B$12)) | L14: =SUMPRODUCT(($A$4:$A$2271=J14)*$E$4:$E$2271*$C$4:$C$2271)/SUMPRODUCT(($A$4:$A$2271=J14)*$E$4:$E$2271)-SUMPRODUCT(($A$4:$A$2271=J14)*0.5^((H14-$B$4:$B$2271)/'2_Params'!$B$12)*$C$4:$C$2271)/SUMPRODUCT(($A$4:$A$2271=J14)*0.5^((H14-$B$4:$B$2271)/'2_Params'!$B$12)) | M14: =K14-L14 | N14: -0.16229916 | O14: =ABS(M14-N14)
A15: ='1_Raw_Games'!D14 | B15: ='1_Raw_Games'!B14 | C15: ='1_Raw_Games'!P14 | D15: =COUNTIFS($A$4:$A$2271,A15,$B$4:$B$2271,">"&B15) | E15: =IF(D15<'2_Params'!$B$13,1,0) | G15: ='1_Raw_Games'!A1148 | H15: ='1_Raw_Games'!B1148 | I15: ='1_Raw_Games'!D1148 | J15: ='1_Raw_Games'!C1148 | K15: =SUMPRODUCT(($A$4:$A$2271=I15)*$E$4:$E$2271*$C$4:$C$2271)/SUMPRODUCT(($A$4:$A$2271=I15)*$E$4:$E$2271)-SUMPRODUCT(($A$4:$A$2271=I15)*0.5^((H15-$B$4:$B$2271)/'2_Params'!$B$12)*$C$4:$C$2271)/SUMPRODUCT(($A$4:$A$2271=I15)*0.5^((H15-$B$4:$B$2271)/'2_Params'!$B$12)) | L15: =SUMPRODUCT(($A$4:$A$2271=J15)*$E$4:$E$2271*$C$4:$C$2271)/SUMPRODUCT(($A$4:$A$2271=J15)*$E$4:$E$2271)-SUMPRODUCT(($A$4:$A$2271=J15)*0.5^((H15-$B$4:$B$2271)/'2_Params'!$B$12)*$C$4:$C$2271)/SUMPRODUCT(($A$4:$A$2271=J15)*0.5^((H15-$B$4:$B$2271)/'2_Params'!$B$12)) | M15: =K15-L15 | N15: -1.9519936 | O15: =ABS(M15-N15)
... A99: ='1_Raw_Games'!D98 | B99: ='1_Raw_Games'!B98 | C99: ='1_Raw_Games'!P98 | D99: =COUNTIFS($A$4:$A$2271,A99,$B$4:$B$2271,">"&B99) | E99: =IF(D99<'2_Params'!$B$13,1,0) | G99: ='1_Raw_Games'!A1232 | H99: ='1_Raw_Games'!B1232 | I99: ='1_Raw_Games'!D1232 | J99: ='1_Raw_Games'!C1232 | K99: =SUMPRODUCT(($A$4:$A$2271=I99)*$E$4:$E$2271*$C$4:$C$2271)/SUMPRODUCT(($A$4:$A$2271=I99)*$E$4:$E$2271)-SUMPRODUCT(($A$4:$A$2271=I99)*0.5^((H99-$B$4:$B$2271)/'2_Params'!$B$12)*$C$4:$C$2271)/SUMPRODUCT(($A$4:$A$2271=I99)*0.5^((H99-$B$4:$B$2271)/'2_Params'!$B$12)) | L99: =SUMPRODUCT(($A$4:$A$2271=J99)*$E$4:$E$2271*$C$4:$C$2271)/SUMPRODUCT(($A$4:$A$2271=J99)*$E$4:$E$2271)-SUMPRODUCT(($A$4:$A$2271=J99)*0.5^((H99-$B$4:$B$2271)/'2_Params'!$B$12)*$C$4:$C$2271)/SUMPRODUCT(($A$4:$A$2271=J99)*0.5^((H99-$B$4:$B$2271)/'2_Params'!$B$12)) | M99: =K99-L99 | N99: 10.404611 | O99: =ABS(M99-N99)
A100: ='1_Raw_Games'!D99 | B100: ='1_Raw_Games'!B99 | C100: ='1_Raw_Games'!P99 | D100: =COUNTIFS($A$4:$A$2271,A100,$B$4:$B$2271,">"&B100) | E100: =IF(D100<'2_Params'!$B$13,1,0) | G100: max |delta|: | H100: =MAX(O4:O99)
A101: ='1_Raw_Games'!D100 | B101: ='1_Raw_Games'!B100 | C101: ='1_Raw_Games'!P100 | D101: =COUNTIFS($A$4:$A$2271,A101,$B$4:$B$2271,">"&B101) | E101: =IF(D101<'2_Params'!$B$13,1,0)
A102: ='1_Raw_Games'!D101 | B102: ='1_Raw_Games'!B101 | C102: ='1_Raw_Games'!P101 | D102: =COUNTIFS($A$4:$A$2271,A102,$B$4:$B$2271,">"&B102) | E102: =IF(D102<'2_Params'!$B$13,1,0)
A103: ='1_Raw_Games'!D102 | B103: ='1_Raw_Games'!B102 | C103: ='1_Raw_Games'!P102 | D103: =COUNTIFS($A$4:$A$2271,A103,$B$4:$B$2271,">"&B103) | E103: =IF(D103<'2_Params'!$B$13,1,0)
A104: ='1_Raw_Games'!D103 | B104: ='1_Raw_Games'!B103 | C104: ='1_Raw_Games'!P103 | D104: =COUNTIFS($A$4:$A$2271,A104,$B$4:$B$2271,">"&B104) | E104: =IF(D104<'2_Params'!$B$13,1,0)
A105: ='1_Raw_Games'!D104 | B105: ='1_Raw_Games'!B104 | C105: ='1_Raw_Games'!P104 | D105: =COUNTIFS($A$4:$A$2271,A105,$B$4:$B$2271,">"&B105) | E105: =IF(D105<'2_Params'!$B$13,1,0)
A106: ='1_Raw_Games'!D105 | B106: ='1_Raw_Games'!B105 | C106: ='1_Raw_Games'!P105 | D106: =COUNTIFS($A$4:$A$2271,A106,$B$4:$B$2271,">"&B106) | E106: =IF(D106<'2_Params'!$B$13,1,0)
A107: ='1_Raw_Games'!D106 | B107: ='1_Raw_Games'!B106 | C107: ='1_Raw_Games'!P106 | D107: =COUNTIFS($A$4:$A$2271,A107,$B$4:$B$2271,">"&B107) | E107: =IF(D107<'2_Params'!$B$13,1,0)
A108: ='1_Raw_Games'!D107 | B108: ='1_Raw_Games'!B107 | C108: ='1_Raw_Games'!P107 | D108: =COUNTIFS($A$4:$A$2271,A108,$B$4:$B$2271,">"&B108) | E108: =IF(D108<'2_Params'!$B$13,1,0)
A109: ='1_Raw_Games'!D108 | B109: ='1_Raw_Games'!B108 | C109: ='1_Raw_Games'!P108 | D109: =COUNTIFS($A$4:$A$2271,A109,$B$4:$B$2271,">"&B109) | E109: =IF(D109<'2_Params'!$B$13,1,0)
A110: ='1_Raw_Games'!D109 | B110: ='1_Raw_Games'!B109 | C110: ='1_Raw_Games'!P109 | D110: =COUNTIFS($A$4:$A$2271,A110,$B$4:$B$2271,">"&B110) | E110: =IF(D110<'2_Params'!$B$13,1,0)
A111: ='1_Raw_Games'!D110 | B111: ='1_Raw_Games'!B110 | C111: ='1_Raw_Games'!P110 | D111: =COUNTIFS($A$4:$A$2271,A111,$B$4:$B$2271,">"&B111) | E111: =IF(D111<'2_Params'!$B$13,1,0)
A112: ='1_Raw_Games'!D111 | B112: ='1_Raw_Games'!B111 | C112: ='1_Raw_Games'!P111 | D112: =COUNTIFS($A$4:$A$2271,A112,$B$4:$B$2271,">"&B112) | E112: =IF(D112<'2_Params'!$B$13,1,0)
... A1137: ='1_Raw_Games'!D1136 | B1137: ='1_Raw_Games'!B1136 | C1137: ='1_Raw_Games'!P1136 | D1137: =COUNTIFS($A$4:$A$2271,A1137,$B$4:$B$2271,">"&B1137) | E1137: =IF(D1137<'2_Params'!$B$13,1,0)
A1138: ='1_Raw_Games'!C3 | B1138: ='1_Raw_Games'!B3 | C1138: =-'1_Raw_Games'!P3 | D1138: =COUNTIFS($A$4:$A$2271,A1138,$B$4:$B$2271,">"&B1138) | E1138: =IF(D1138<'2_Params'!$B$13,1,0)
A1139: ='1_Raw_Games'!C4 | B1139: ='1_Raw_Games'!B4 | C1139: =-'1_Raw_Games'!P4 | D1139: =COUNTIFS($A$4:$A$2271,A1139,$B$4:$B$2271,">"&B1139) | E1139: =IF(D1139<'2_Params'!$B$13,1,0)
A1140: ='1_Raw_Games'!C5 | B1140: ='1_Raw_Games'!B5 | C1140: =-'1_Raw_Games'!P5 | D1140: =COUNTIFS($A$4:$A$2271,A1140,$B$4:$B$2271,">"&B1140) | E1140: =IF(D1140<'2_Params'!$B$13,1,0)
A1141: ='1_Raw_Games'!C6 | B1141: ='1_Raw_Games'!B6 | C1141: =-'1_Raw_Games'!P6 | D1141: =COUNTIFS($A$4:$A$2271,A1141,$B$4:$B$2271,">"&B1141) | E1141: =IF(D1141<'2_Params'!$B$13,1,0)
A1142: ='1_Raw_Games'!C7 | B1142: ='1_Raw_Games'!B7 | C1142: =-'1_Raw_Games'!P7 | D1142: =COUNTIFS($A$4:$A$2271,A1142,$B$4:$B$2271,">"&B1142) | E1142: =IF(D1142<'2_Params'!$B$13,1,0)
A1143: ='1_Raw_Games'!C8 | B1143: ='1_Raw_Games'!B8 | C1143: =-'1_Raw_Games'!P8 | D1143: =COUNTIFS($A$4:$A$2271,A1143,$B$4:$B$2271,">"&B1143) | E1143: =IF(D1143<'2_Params'!$B$13,1,0)
A1144: ='1_Raw_Games'!C9 | B1144: ='1_Raw_Games'!B9 | C1144: =-'1_Raw_Games'!P9 | D1144: =COUNTIFS($A$4:$A$2271,A1144,$B$4:$B$2271,">"&B1144) | E1144: =IF(D1144<'2_Params'!$B$13,1,0)
A1145: ='1_Raw_Games'!C10 | B1145: ='1_Raw_Games'!B10 | C1145: =-'1_Raw_Games'!P10 | D1145: =COUNTIFS($A$4:$A$2271,A1145,$B$4:$B$2271,">"&B1145) | E1145: =IF(D1145<'2_Params'!$B$13,1,0)
A1146: ='1_Raw_Games'!C11 | B1146: ='1_Raw_Games'!B11 | C1146: =-'1_Raw_Games'!P11 | D1146: =COUNTIFS($A$4:$A$2271,A1146,$B$4:$B$2271,">"&B1146) | E1146: =IF(D1146<'2_Params'!$B$13,1,0)
A1147: ='1_Raw_Games'!C12 | B1147: ='1_Raw_Games'!B12 | C1147: =-'1_Raw_Games'!P12 | D1147: =COUNTIFS($A$4:$A$2271,A1147,$B$4:$B$2271,">"&B1147) | E1147: =IF(D1147<'2_Params'!$B$13,1,0)
...

Sheet 7_Fit_Selection_Models
AI1: Panel 2: rank model — L2 logistic on standardized (bt_logit, trend_diff), C=0.1.
A4: row | B4: elo (raw) | C4: y | D4: z it1 | E4: p it1 | F4: z it2 | G4: p it2 | H4: z it3 | I4: p it3 | J4: z it4 | K4: p it4 | L4: z it5 | M4: p it5 | N4: z it6 | O4: p it6 | P4: z it7 | Q4: p it7 | R4: z it8 | S4: p it8 | T4: STANDARDIZER (population std, as sklearn) | AI4: row | AJ4: bt (raw) | AK4: trend (raw) | AL4: y | AM4: z it1 | AN4: p it1 | AO4: z it2 | AP4: p it2 | AQ4: z it3 | AR4: p it3 | AS4: z it4 | AT4: p it4 | AU4: z it5 | AV4: p it5 | AW4: z it6 | AX4: p it6 | AY4: z it7 | AZ4: p it7 | BA4: z it8 | BB4: p it8 | BC4: STANDARDIZER (population std, as sklearn)
A5: ='4_Seq_Features'!A3 | B5: ='4_Seq_Features'!F3 | C5: ='4_Seq_Features'!E3 | D5: =$U$12*((B5)-$U$5)/$U$6+$U$13 | E5: =1/(1+EXP(-D5)) | F5: =$V$12*((B5)-$U$5)/$U$6+$V$13 | G5: =1/(1+EXP(-F5)) | H5: =$W$12*((B5)-$U$5)/$U$6+$W$13 | I5: =1/(1+EXP(-H5)) | J5: =$X$12*((B5)-$U$5)/$U$6+$X$13 | K5: =1/(1+EXP(-J5)) | L5: =$Y$12*((B5)-$U$5)/$U$6+$Y$13 | M5: =1/(1+EXP(-L5)) | N5: =$Z$12*((B5)-$U$5)/$U$6+$Z$13 | O5: =1/(1+EXP(-N5)) | P5: =$AA$12*((B5)-$U$5)/$U$6+$AA$13 | Q5: =1/(1+EXP(-P5)) | R5: =$AB$12*((B5)-$U$5)/$U$6+$AB$13 | S5: =1/(1+EXP(-R5)) | T5: mean elo | U5: =AVERAGE(B$5:B$899) | AI5: ='4_Seq_Features'!A3 | AJ5: ='4_Seq_Features'!G3 | AK5: ='4_Seq_Features'!H3 | AL5: ='4_Seq_Features'!E3 | AM5: =$BD$14*((AJ5)-$BD$5)/$BD$6+$BD$15*((AK5)-$BD$7)/$BD$8+$BD$16 | AN5: =1/(1+EXP(-AM5)) | AO5: =$BE$14*((AJ5)-$BD$5)/$BD$6+$BE$15*((AK5)-$BD$7)/$BD$8+$BE$16 | AP5: =1/(1+EXP(-AO5)) | AQ5: =$BF$14*((AJ5)-$BD$5)/$BD$6+$BF$15*((AK5)-$BD$7)/$BD$8+$BF$16 | AR5: =1/(1+EXP(-AQ5)) | AS5: =$BG$14*((AJ5)-$BD$5)/$BD$6+$BG$15*((AK5)-$BD$7)/$BD$8+$BG$16 | AT5: =1/(1+EXP(-AS5)) | AU5: =$BH$14*((AJ5)-$BD$5)/$BD$6+$BH$15*((AK5)-$BD$7)/$BD$8+$BH$16 | AV5: =1/(1+EXP(-AU5)) | AW5: =$BI$14*((AJ5)-$BD$5)/$BD$6+$BI$15*((AK5)-$BD$7)/$BD$8+$BI$16 | AX5: =1/(1+EXP(-AW5)) | AY5: =$BJ$14*((AJ5)-$BD$5)/$BD$6+$BJ$15*((AK5)-$BD$7)/$BD$8+$BJ$16 | AZ5: =1/(1+EXP(-AY5)) | BA5: =$BK$14*((AJ5)-$BD$5)/$BD$6+$BK$15*((AK5)-$BD$7)/$BD$8+$BK$16 | BB5: =1/(1+EXP(-BA5)) | BC5: mean bt | BD5: =AVERAGE(AJ$5:AJ$899)
A6: ='4_Seq_Features'!A4 | B6: ='4_Seq_Features'!F4 | C6: ='4_Seq_Features'!E4 | D6: =$U$12*((B6)-$U$5)/$U$6+$U$13 | E6: =1/(1+EXP(-D6)) | F6: =$V$12*((B6)-$U$5)/$U$6+$V$13 | G6: =1/(1+EXP(-F6)) | H6: =$W$12*((B6)-$U$5)/$U$6+$W$13 | I6: =1/(1+EXP(-H6)) | J6: =$X$12*((B6)-$U$5)/$U$6+$X$13 | K6: =1/(1+EXP(-J6)) | L6: =$Y$12*((B6)-$U$5)/$U$6+$Y$13 | M6: =1/(1+EXP(-L6)) | N6: =$Z$12*((B6)-$U$5)/$U$6+$Z$13 | O6: =1/(1+EXP(-N6)) | P6: =$AA$12*((B6)-$U$5)/$U$6+$AA$13 | Q6: =1/(1+EXP(-P6)) | R6: =$AB$12*((B6)-$U$5)/$U$6+$AB$13 | S6: =1/(1+EXP(-R6)) | T6: scale elo | U6: =SQRT(SUMPRODUCT((B$5:B$899-U5)^2)/COUNT(B$5:B$899)) | AI6: ='4_Seq_Features'!A4 | AJ6: ='4_Seq_Features'!G4 | AK6: ='4_Seq_Features'!H4 | AL6: ='4_Seq_Features'!E4 | AM6: =$BD$14*((AJ6)-$BD$5)/$BD$6+$BD$15*((AK6)-$BD$7)/$BD$8+$BD$16 | AN6: =1/(1+EXP(-AM6)) | AO6: =$BE$14*((AJ6)-$BD$5)/$BD$6+$BE$15*((AK6)-$BD$7)/$BD$8+$BE$16 | AP6: =1/(1+EXP(-AO6)) | AQ6: =$BF$14*((AJ6)-$BD$5)/$BD$6+$BF$15*((AK6)-$BD$7)/$BD$8+$BF$16 | AR6: =1/(1+EXP(-AQ6)) | AS6: =$BG$14*((AJ6)-$BD$5)/$BD$6+$BG$15*((AK6)-$BD$7)/$BD$8+$BG$16 | AT6: =1/(1+EXP(-AS6)) | AU6: =$BH$14*((AJ6)-$BD$5)/$BD$6+$BH$15*((AK6)-$BD$7)/$BD$8+$BH$16 | AV6: =1/(1+EXP(-AU6)) | AW6: =$BI$14*((AJ6)-$BD$5)/$BD$6+$BI$15*((AK6)-$BD$7)/$BD$8+$BI$16 | AX6: =1/(1+EXP(-AW6)) | AY6: =$BJ$14*((AJ6)-$BD$5)/$BD$6+$BJ$15*((AK6)-$BD$7)/$BD$8+$BJ$16 | AZ6: =1/(1+EXP(-AY6)) | BA6: =$BK$14*((AJ6)-$BD$5)/$BD$6+$BK$15*((AK6)-$BD$7)/$BD$8+$BK$16 | BB6: =1/(1+EXP(-BA6)) | BC6: scale bt | BD6: =SQRT(SUMPRODUCT((AJ$5:AJ$899-BD5)^2)/COUNT(AJ$5:AJ$899))
A7: ='4_Seq_Features'!A5 | B7: ='4_Seq_Features'!F5 | C7: ='4_Seq_Features'!E5 | D7: =$U$12*((B7)-$U$5)/$U$6+$U$13 | E7: =1/(1+EXP(-D7)) | F7: =$V$12*((B7)-$U$5)/$U$6+$V$13 | G7: =1/(1+EXP(-F7)) | H7: =$W$12*((B7)-$U$5)/$U$6+$W$13 | I7: =1/(1+EXP(-H7)) | J7: =$X$12*((B7)-$U$5)/$U$6+$X$13 | K7: =1/(1+EXP(-J7)) | L7: =$Y$12*((B7)-$U$5)/$U$6+$Y$13 | M7: =1/(1+EXP(-L7)) | N7: =$Z$12*((B7)-$U$5)/$U$6+$Z$13 | O7: =1/(1+EXP(-N7)) | P7: =$AA$12*((B7)-$U$5)/$U$6+$AA$13 | Q7: =1/(1+EXP(-P7)) | R7: =$AB$12*((B7)-$U$5)/$U$6+$AB$13 | S7: =1/(1+EXP(-R7)) | AI7: ='4_Seq_Features'!A5 | AJ7: ='4_Seq_Features'!G5 | AK7: ='4_Seq_Features'!H5 | AL7: ='4_Seq_Features'!E5 | AM7: =$BD$14*((AJ7)-$BD$5)/$BD$6+$BD$15*((AK7)-$BD$7)/$BD$8+$BD$16 | AN7: =1/(1+EXP(-AM7)) | AO7: =$BE$14*((AJ7)-$BD$5)/$BD$6+$BE$15*((AK7)-$BD$7)/$BD$8+$BE$16 | AP7: =1/(1+EXP(-AO7)) | AQ7: =$BF$14*((AJ7)-$BD$5)/$BD$6+$BF$15*((AK7)-$BD$7)/$BD$8+$BF$16 | AR7: =1/(1+EXP(-AQ7)) | AS7: =$BG$14*((AJ7)-$BD$5)/$BD$6+$BG$15*((AK7)-$BD$7)/$BD$8+$BG$16 | AT7: =1/(1+EXP(-AS7)) | AU7: =$BH$14*((AJ7)-$BD$5)/$BD$6+$BH$15*((AK7)-$BD$7)/$BD$8+$BH$16 | AV7: =1/(1+EXP(-AU7)) | AW7: =$BI$14*((AJ7)-$BD$5)/$BD$6+$BI$15*((AK7)-$BD$7)/$BD$8+$BI$16 | AX7: =1/(1+EXP(-AW7)) | AY7: =$BJ$14*((AJ7)-$BD$5)/$BD$6+$BJ$15*((AK7)-$BD$7)/$BD$8+$BJ$16 | AZ7: =1/(1+EXP(-AY7)) | BA7: =$BK$14*((AJ7)-$BD$5)/$BD$6+$BK$15*((AK7)-$BD$7)/$BD$8+$BK$16 | BB7: =1/(1+EXP(-BA7)) | BC7: mean trend | BD7: =AVERAGE(AK$5:AK$899)
A8: ='4_Seq_Features'!A6 | B8: ='4_Seq_Features'!F6 | C8: ='4_Seq_Features'!E6 | D8: =$U$12*((B8)-$U$5)/$U$6+$U$13 | E8: =1/(1+EXP(-D8)) | F8: =$V$12*((B8)-$U$5)/$U$6+$V$13 | G8: =1/(1+EXP(-F8)) | H8: =$W$12*((B8)-$U$5)/$U$6+$W$13 | I8: =1/(1+EXP(-H8)) | J8: =$X$12*((B8)-$U$5)/$U$6+$X$13 | K8: =1/(1+EXP(-J8)) | L8: =$Y$12*((B8)-$U$5)/$U$6+$Y$13 | M8: =1/(1+EXP(-L8)) | N8: =$Z$12*((B8)-$U$5)/$U$6+$Z$13 | O8: =1/(1+EXP(-N8)) | P8: =$AA$12*((B8)-$U$5)/$U$6+$AA$13 | Q8: =1/(1+EXP(-P8)) | R8: =$AB$12*((B8)-$U$5)/$U$6+$AB$13 | S8: =1/(1+EXP(-R8)) | AI8: ='4_Seq_Features'!A6 | AJ8: ='4_Seq_Features'!G6 | AK8: ='4_Seq_Features'!H6 | AL8: ='4_Seq_Features'!E6 | AM8: =$BD$14*((AJ8)-$BD$5)/$BD$6+$BD$15*((AK8)-$BD$7)/$BD$8+$BD$16 | AN8: =1/(1+EXP(-AM8)) | AO8: =$BE$14*((AJ8)-$BD$5)/$BD$6+$BE$15*((AK8)-$BD$7)/$BD$8+$BE$16 | AP8: =1/(1+EXP(-AO8)) | AQ8: =$BF$14*((AJ8)-$BD$5)/$BD$6+$BF$15*((AK8)-$BD$7)/$BD$8+$BF$16 | AR8: =1/(1+EXP(-AQ8)) | AS8: =$BG$14*((AJ8)-$BD$5)/$BD$6+$BG$15*((AK8)-$BD$7)/$BD$8+$BG$16 | AT8: =1/(1+EXP(-AS8)) | AU8: =$BH$14*((AJ8)-$BD$5)/$BD$6+$BH$15*((AK8)-$BD$7)/$BD$8+$BH$16 | AV8: =1/(1+EXP(-AU8)) | AW8: =$BI$14*((AJ8)-$BD$5)/$BD$6+$BI$15*((AK8)-$BD$7)/$BD$8+$BI$16 | AX8: =1/(1+EXP(-AW8)) | AY8: =$BJ$14*((AJ8)-$BD$5)/$BD$6+$BJ$15*((AK8)-$BD$7)/$BD$8+$BJ$16 | AZ8: =1/(1+EXP(-AY8)) | BA8: =$BK$14*((AJ8)-$BD$5)/$BD$6+$BK$15*((AK8)-$BD$7)/$BD$8+$BK$16 | BB8: =1/(1+EXP(-BA8)) | BC8: scale trend | BD8: =SQRT(SUMPRODUCT((AK$5:AK$899-BD7)^2)/COUNT(AK$5:AK$899))
A9: ='4_Seq_Features'!A7 | B9: ='4_Seq_Features'!F7 | C9: ='4_Seq_Features'!E7 | D9: =$U$12*((B9)-$U$5)/$U$6+$U$13 | E9: =1/(1+EXP(-D9)) | F9: =$V$12*((B9)-$U$5)/$U$6+$V$13 | G9: =1/(1+EXP(-F9)) | H9: =$W$12*((B9)-$U$5)/$U$6+$W$13 | I9: =1/(1+EXP(-H9)) | J9: =$X$12*((B9)-$U$5)/$U$6+$X$13 | K9: =1/(1+EXP(-J9)) | L9: =$Y$12*((B9)-$U$5)/$U$6+$Y$13 | M9: =1/(1+EXP(-L9)) | N9: =$Z$12*((B9)-$U$5)/$U$6+$Z$13 | O9: =1/(1+EXP(-N9)) | P9: =$AA$12*((B9)-$U$5)/$U$6+$AA$13 | Q9: =1/(1+EXP(-P9)) | R9: =$AB$12*((B9)-$U$5)/$U$6+$AB$13 | S9: =1/(1+EXP(-R9)) | AI9: ='4_Seq_Features'!A7 | AJ9: ='4_Seq_Features'!G7 | AK9: ='4_Seq_Features'!H7 | AL9: ='4_Seq_Features'!E7 | AM9: =$BD$14*((AJ9)-$BD$5)/$BD$6+$BD$15*((AK9)-$BD$7)/$BD$8+$BD$16 | AN9: =1/(1+EXP(-AM9)) | AO9: =$BE$14*((AJ9)-$BD$5)/$BD$6+$BE$15*((AK9)-$BD$7)/$BD$8+$BE$16 | AP9: =1/(1+EXP(-AO9)) | AQ9: =$BF$14*((AJ9)-$BD$5)/$BD$6+$BF$15*((AK9)-$BD$7)/$BD$8+$BF$16 | AR9: =1/(1+EXP(-AQ9)) | AS9: =$BG$14*((AJ9)-$BD$5)/$BD$6+$BG$15*((AK9)-$BD$7)/$BD$8+$BG$16 | AT9: =1/(1+EXP(-AS9)) | AU9: =$BH$14*((AJ9)-$BD$5)/$BD$6+$BH$15*((AK9)-$BD$7)/$BD$8+$BH$16 | AV9: =1/(1+EXP(-AU9)) | AW9: =$BI$14*((AJ9)-$BD$5)/$BD$6+$BI$15*((AK9)-$BD$7)/$BD$8+$BI$16 | AX9: =1/(1+EXP(-AW9)) | AY9: =$BJ$14*((AJ9)-$BD$5)/$BD$6+$BJ$15*((AK9)-$BD$7)/$BD$8+$BJ$16 | AZ9: =1/(1+EXP(-AY9)) | BA9: =$BK$14*((AJ9)-$BD$5)/$BD$6+$BK$15*((AK9)-$BD$7)/$BD$8+$BK$16 | BB9: =1/(1+EXP(-BA9))
A10: ='4_Seq_Features'!A8 | B10: ='4_Seq_Features'!F8 | C10: ='4_Seq_Features'!E8 | D10: =$U$12*((B10)-$U$5)/$U$6+$U$13 | E10: =1/(1+EXP(-D10)) | F10: =$V$12*((B10)-$U$5)/$U$6+$V$13 | G10: =1/(1+EXP(-F10)) | H10: =$W$12*((B10)-$U$5)/$U$6+$W$13 | I10: =1/(1+EXP(-H10)) | J10: =$X$12*((B10)-$U$5)/$U$6+$X$13 | K10: =1/(1+EXP(-J10)) | L10: =$Y$12*((B10)-$U$5)/$U$6+$Y$13 | M10: =1/(1+EXP(-L10)) | N10: =$Z$12*((B10)-$U$5)/$U$6+$Z$13 | O10: =1/(1+EXP(-N10)) | P10: =$AA$12*((B10)-$U$5)/$U$6+$AA$13 | Q10: =1/(1+EXP(-P10)) | R10: =$AB$12*((B10)-$U$5)/$U$6+$AB$13 | S10: =1/(1+EXP(-R10)) | T10: NEWTON ITERATIONS (start at 0; each column solves the penalized IRLS step from the previous) | AI10: ='4_Seq_Features'!A8 | AJ10: ='4_Seq_Features'!G8 | AK10: ='4_Seq_Features'!H8 | AL10: ='4_Seq_Features'!E8 | AM10: =$BD$14*((AJ10)-$BD$5)/$BD$6+$BD$15*((AK10)-$BD$7)/$BD$8+$BD$16 | AN10: =1/(1+EXP(-AM10)) | AO10: =$BE$14*((AJ10)-$BD$5)/$BD$6+$BE$15*((AK10)-$BD$7)/$BD$8+$BE$16 | AP10: =1/(1+EXP(-AO10)) | AQ10: =$BF$14*((AJ10)-$BD$5)/$BD$6+$BF$15*((AK10)-$BD$7)/$BD$8+$BF$16 | AR10: =1/(1+EXP(-AQ10)) | AS10: =$BG$14*((AJ10)-$BD$5)/$BD$6+$BG$15*((AK10)-$BD$7)/$BD$8+$BG$16 | AT10: =1/(1+EXP(-AS10)) | AU10: =$BH$14*((AJ10)-$BD$5)/$BD$6+$BH$15*((AK10)-$BD$7)/$BD$8+$BH$16 | AV10: =1/(1+EXP(-AU10)) | AW10: =$BI$14*((AJ10)-$BD$5)/$BD$6+$BI$15*((AK10)-$BD$7)/$BD$8+$BI$16 | AX10: =1/(1+EXP(-AW10)) | AY10: =$BJ$14*((AJ10)-$BD$5)/$BD$6+$BJ$15*((AK10)-$BD$7)/$BD$8+$BJ$16 | AZ10: =1/(1+EXP(-AY10)) | BA10: =$BK$14*((AJ10)-$BD$5)/$BD$6+$BK$15*((AK10)-$BD$7)/$BD$8+$BK$16 | BB10: =1/(1+EXP(-BA10))
A11: ='4_Seq_Features'!A9 | B11: ='4_Seq_Features'!F9 | C11: ='4_Seq_Features'!E9 | D11: =$U$12*((B11)-$U$5)/$U$6+$U$13 | E11: =1/(1+EXP(-D11)) | F11: =$V$12*((B11)-$U$5)/$U$6+$V$13 | G11: =1/(1+EXP(-F11)) | H11: =$W$12*((B11)-$U$5)/$U$6+$W$13 | I11: =1/(1+EXP(-H11)) | J11: =$X$12*((B11)-$U$5)/$U$6+$X$13 | K11: =1/(1+EXP(-J11)) | L11: =$Y$12*((B11)-$U$5)/$U$6+$Y$13 | M11: =1/(1+EXP(-L11)) | N11: =$Z$12*((B11)-$U$5)/$U$6+$Z$13 | O11: =1/(1+EXP(-N11)) | P11: =$AA$12*((B11)-$U$5)/$U$6+$AA$13 | Q11: =1/(1+EXP(-P11)) | R11: =$AB$12*((B11)-$U$5)/$U$6+$AB$13 | S11: =1/(1+EXP(-R11)) | T11: param | U11: it 0 | V11: it 1 | W11: it 2 | X11: it 3 | Y11: it 4 | Z11: it 5 | AA11: it 6 | AB11: it 7 | AC11: it 8 | AI11: ='4_Seq_Features'!A9 | AJ11: ='4_Seq_Features'!G9 | AK11: ='4_Seq_Features'!H9 | AL11: ='4_Seq_Features'!E9 | AM11: =$BD$14*((AJ11)-$BD$5)/$BD$6+$BD$15*((AK11)-$BD$7)/$BD$8+$BD$16 | AN11: =1/(1+EXP(-AM11)) | AO11: =$BE$14*((AJ11)-$BD$5)/$BD$6+$BE$15*((AK11)-$BD$7)/$BD$8+$BE$16 | AP11: =1/(1+EXP(-AO11)) | AQ11: =$BF$14*((AJ11)-$BD$5)/$BD$6+$BF$15*((AK11)-$BD$7)/$BD$8+$BF$16 | AR11: =1/(1+EXP(-AQ11)) | AS11: =$BG$14*((AJ11)-$BD$5)/$BD$6+$BG$15*((AK11)-$BD$7)/$BD$8+$BG$16 | AT11: =1/(1+EXP(-AS11)) | AU11: =$BH$14*((AJ11)-$BD$5)/$BD$6+$BH$15*((AK11)-$BD$7)/$BD$8+$BH$16 | AV11: =1/(1+EXP(-AU11)) | AW11: =$BI$14*((AJ11)-$BD$5)/$BD$6+$BI$15*((AK11)-$BD$7)/$BD$8+$BI$16 | AX11: =1/(1+EXP(-AW11)) | AY11: =$BJ$14*((AJ11)-$BD$5)/$BD$6+$BJ$15*((AK11)-$BD$7)/$BD$8+$BJ$16 | AZ11: =1/(1+EXP(-AY11)) | BA11: =$BK$14*((AJ11)-$BD$5)/$BD$6+$BK$15*((AK11)-$BD$7)/$BD$8+$BK$16 | BB11: =1/(1+EXP(-BA11))
